Workbook
Name Birth_Date: #REF!
Name Birth_Date: #REF!
Name Birth_Date: #REF!
Name Birth_Date: #REF!
Name Birth_Date: #REF!
Name Birth_Date: #REF!
Name Birth_Date: #REF!
Name Birth_Date: #REF!
Name Birth_Date: #REF!
Name Category_ID: #REF!
Name Category_ID: #REF!
Name Category_ID: #REF!
Name Category_ID: #REF!
Name Category_ID: #REF!
Name Category_ID: #REF!
Name Category_ID: #REF!
Name Category_ID: #REF!
Name Category_ID: #REF!
Name Category_ID: #REF!
Name Category_ID: #REF!
Name Category_ID: #REF!
Name Category_Name: #REF!
Name Category_Name: #REF!
Name Category_Name: #REF!
Name Category_Name: #REF!
Name Category_Name: #REF!
Name Category_Name: #REF!
Name Category_Name: #REF!
Name Category_Name: #REF!
Name Category_Name: #REF!
Name Category_Name: #REF!
Name Category_Name: #REF!
Name Category_Name: #REF!
Name date: [1]list01!$G$1:$G$31
Name date: [1]list01!$G$1:$G$31
Name date: [1]list01!$G$1:$G$31
Name date: [1]list01!$G$1:$G$31
Name date: [1]list01!$G$1:$G$31
Name date: [1]list01!$G$1:$G$31
Name date: [1]list01!$G$1:$G$31
Name date: [1]list01!$G$1:$G$31
Name date: [1]list01!$G$1:$G$31
Name date: [1]list01!$G$1:$G$31
Name date: [1]list01!$G$1:$G$31
Name date: [1]list01!$G$1:$G$31
Name date: [2]list01!$G$1:$G$31
Name date: ข้อมูลพื้นฐาน!$G$1:$G$39
Name Description: #REF!
Name Description: #REF!
Name Description: #REF!
Name Description: #REF!
Name Description: #REF!
Name Description: #REF!
Name Description: #REF!
Name Description: #REF!
Name Description: #REF!
Name Description: #REF!
Name Description: #REF!
Name Description: #REF!
Name Down: [3]คำแนะนำ!#REF!

Sheet HOME
A1: ปพ.5 และ ปพ.6 อัตโนมัติ
A2: สำหรับครูประจำชั้นประถมศึกษา(Version 1.6 ) ปีการศึกษา 2564
A3: จัดทำโดยครูสันติ โลมาอินทร์
A22: หมายเหตุ | B22: ใช้ตัวอักษรแบบ TH SarabunPSK
C23: สีเหลือง กรอกข้อมูลให้ครบแต่ไม่ต้องพิมพ์
C24: สีเขียว กรอกข้อมูลให้ครบ
C25: ปริ้นแล้วกรอกข้อมูลด้วยตนเอง
C26: สีแดงระบบจะทำงานอัตโนมัติ

Sheet ข้อมูลพื้นฐาน
A1: ข้อมูลพื้นฐาน
A3: โรงเรียน | B3: บ้านคลองน้ำโจน สาขาบ้านสระหลวง | K3: นายทะเบียนวัดและประเมินผล
A4: สังกัด | B4: สำนักงานเขตพื้นที่การศึกษาประถมศึกษา นครสวรรค์ เขต 2 | K4: รองผู้อำนวยการ
A5: ตำบล | B5: แม่วงก์ | H5: มาเรียน | I5: / | K5: หัวหน้าวิชาการ
A6: อำเภอ | B6: แม่วงก์ | H6: ป่วย | I6: ป
A7: จังหวัด | B7: นครสวรรค์ | H7: ลา | I7: ล
A8: ปีการศึกษา | B8: 2565 | H8: ขาดเรียน | I8: ข
A9: ระดับชั้นประถมศึกษาปีที่
A10: ครูประจำชั้น
A11: ชื่อผู้บริหารสถานศึกษา/รักษาการในตำแหน่ง | G11: ตำแหน่ง | H11: ผู้อำนวยการ
A12: นายทะเบียนวัดและประเมินผล
A13: วันอนุมัติผล | C13: เดือน | E13: พ.ศ.
A14: วิชาพื้นฐาน | B14: ครูประจำวิชา | C14: รหัสวิชา | D14: สัดส่วนคะแนน | F14: ตัวชี้วัด/ภาคเรียน | H14: น้ำหนัก/หน่วย/ปี
A15: ภาษาไทย | D15: 70 | E15: 30
A16: คณิตศาสตร์ | D16: 70 | E16: 30
A17: วิทยาศาสตร์และเทคโนโลยี | D17: 70 | E17: 30
A18: สังคมศึกษา ศาสนา และวัฒนธรรม | D18: 70 | E18: 30
A19: ประวัติศาสตร์ | D19: 80 | E19: 20
A20: สุขศึกษาและพลศึกษา | D20: 80 | E20: 20
A21: ศิลปะ | D21: 80 | E21: 20
A22: การงานอาชีพ | D22: 80 | E22: 20
A23: ภาษาอังกฤษ | D23: 70 | E23: 30
A24: วิชาเพิ่มเติม | B24: ครูประจำวิชา | C24: รหัสวิชา | D24: สัดส่วนคะแนน | F24: ตัวชี้วัด/ภาคเรียน | H24: น้ำหนัก/หน่วย/ปี
A25: ภาษาอังกฤษเพื่อการสื่อสาร | D25: 80 | E25: 20
H37: =SUM(H15:H36) -> 0

Sheet กรอกข้อมูล นร1
A2: ="ข้อมูลเกี่ยวข้องกับนักเรียนชั้นประถมศึกษาปีที่ "&ข้อมูลพื้นฐาน!B9&" ปีการศึกษา "&ข้อมูลพื้นฐาน!B8 -> ข้อมูลเกี่ยวข้องกับนักเรียนชั้นประถมศึกษาปีที่ ปีการศึกษา 2565 | G2: ="ข้อมูลเกี่ยวข้องกับนักเรียนชั้นประถมศึกษาปีที่ "&ข้อมูลพื้นฐาน!B9&" ปีการศึกษา "&ข้อมูลพื้นฐาน!B8 -> ข้อมูลเกี่ยวข้องกับนักเรียนชั้นประถมศึกษาปีที่ ปีการศึกษา 2565 | N2: =G2 -> ข้อมูลเกี่ยวข้องกับนักเรียนชั้นประถมศึกษาปีที่ ปีการศึกษา 2565 | S2: =N2 -> ข้อมูลเกี่ยวข้องกับนักเรียนชั้นประถมศึกษาปีที่ ปีการศึกษา 2565
A3: เลขที่ | B3: เลข | C3: ชื่อ-ชื่อสกุล | D3: ข้อมูลนักเรียน | G3: เลขที่ | H3: ชื่อเล่น | I3: เชื้อชาติ | J3: สัญชาติ | K3: ศาสนา | L3: ชื่อบิดา | M3: อาชีพ | N3: ชื่อ มารดา | O3: อาชีพ | P3: ชื่อ-สกุลผู้ปกครอง | Q3: อาชีพ | R3: เกี่ยวข้องเป็น | S3: ที่อยู่ปัจจุบัน
B4: ประจำตัว | D4: เลขประจำตัวประชาชน | E4: ย้าย | F4: วัน/เดือน/ปี เกิด | S4: บ้านเลขที่ | T4: ถนน | U4: ซอย | V4: หมู่ | W4: ตำบล | X4: อำเภอ | Y4: จังหวัด | Z4: โทรศัพท์
A5: 1 | G5: =IF(A5,A5,"") -> 1
G6: =IF(A6,A6,"")
G7: =IF(A7,A7,"")
G8: =IF(A8,A8,"")
G9: =IF(A9,A9,"")
G10: =IF(A10,A10,"")
G11: =IF(A11,A11,"")
G12: =IF(A12,A12,"")
G13: =IF(A13,A13,"")
G14: =IF(A14,A14,"")
G15: =IF(A15,A15,"")
G16: =IF(A16,A16,"")
G17: =IF(A17,A17,"")
... G54: =IF(A54,A54,"")
E58: จำนวนนักเรียน เมื่อต้นปีการศึกษา | N58: =IF(COUNTA(C5:C54),COUNTA(C5:C54),"-") -> - | O58: คน
E59: จำนวนนักเรียน ออกระหว่างปี | N59: =IF(COUNTIF(E5:E54,"ย้าย"),COUNTIF(E5:E54,"ย้าย"),"0") -> 0 | O59: คน
E60: จำนวนนักเรียน เมื่อสิ้นปีการศึกษา | N60: =N58-N59 -> #VALUE! | O60: คน
C64: ย้าย

Sheet ภาพนักเรียน
A1: รูปภาพนักเรียนขนาด 4x5 ซม. | D1: *ควรลดขนาดภาพก่อนแทรกเพราะจะทำให้ไฟล์งานไม่ใหญ่เกินไป
A4: เลขที่ | B4: ชื่อ - สกุล | C4: ภาพนักเรียน
A5: =น้ำหนักส่วนสูง!A3 -> 1 | B5: =น้ำหนักส่วนสูง!B3
A6: =น้ำหนักส่วนสูง!A4 -> 2 | B6: =น้ำหนักส่วนสูง!B4
A7: =น้ำหนักส่วนสูง!A5 -> 3 | B7: =น้ำหนักส่วนสูง!B5
A8: =น้ำหนักส่วนสูง!A6 -> 4 | B8: =น้ำหนักส่วนสูง!B6
A9: =น้ำหนักส่วนสูง!A7 -> 5 | B9: =น้ำหนักส่วนสูง!B7
A10: =น้ำหนักส่วนสูง!A8 -> 6 | B10: =น้ำหนักส่วนสูง!B8
A11: =น้ำหนักส่วนสูง!A9 -> 7 | B11: =น้ำหนักส่วนสูง!B9
A12: =น้ำหนักส่วนสูง!A10 -> 8 | B12: =น้ำหนักส่วนสูง!B10
A13: =น้ำหนักส่วนสูง!A11 -> 9 | B13: =น้ำหนักส่วนสูง!B11
A14: =น้ำหนักส่วนสูง!A12 -> 10 | B14: =น้ำหนักส่วนสูง!B12
A15: =น้ำหนักส่วนสูง!A13 -> 11 | B15: =น้ำหนักส่วนสูง!B13
A16: =น้ำหนักส่วนสูง!A14 -> 12 | B16: =น้ำหนักส่วนสูง!B14
... A54: =น้ำหนักส่วนสูง!A52 -> 50 | B54: =น้ำหนักส่วนสูง!B52

Sheet น้ำหนักส่วนสูง
A1: เลขที่ | B1: ชื่อ-ชื่อสกุล | C1: น้ำหนัก(กก.) | D1: ส่วนสูง(ซม) | E1: น้ำหนัก(กก.) | F1: ส่วนสูง(ซม) | G1: น้ำหนัก(กก.) | H1: ส่วนสูง(ซม) | I1: น้ำหนัก(กก.) | J1: ส่วนสูง(ซม)
C2: พฤษภาคม | E2: สิงหาคม | G2: พฤศจิกายน | I2: กุมภาพันธ์
A3: 1 | B3: =เวลาเรียน1!D7&""
A4: 2 | B4: =เวลาเรียน1!D8&"" | K4: คำชี้แจง : กรอกน้ำหนักและส่วนสูงของนักเรียน
A5: 3 | B5: =เวลาเรียน1!D9&""
A6: 4 | B6: =เวลาเรียน1!D10&""
A7: 5 | B7: =เวลาเรียน1!D11&""
A8: 6 | B8: =เวลาเรียน1!D12&""
A9: 7 | B9: =เวลาเรียน1!D13&""
A10: 8 | B10: =เวลาเรียน1!D14&""
A11: 9 | B11: =เวลาเรียน1!D15&""
A12: 10 | B12: =เวลาเรียน1!D16&""
A13: 11 | B13: =เวลาเรียน1!D17&""
A14: 12 | B14: =เวลาเรียน1!D18&""
A15: 13 | B15: =เวลาเรียน1!D19&""
A16: 14 | B16: =เวลาเรียน1!D20&""
... A52: 50 | B52: =เวลาเรียน1!D56&""

Sheet หน้าปก ปพ.5
W1: ปพ.5
A3: แบบบันทึกผลการพัฒนาคุณภาพผู้เรียน
A4: ="โรงเรียน"&ข้อมูลพื้นฐาน!B3&" "&ข้อมูลพื้นฐาน!B4 -> โรงเรียนบ้านคลองน้ำโจน สาขาบ้านสระหลวง สำนักงานเขตพื้นที่การศึกษาประถมศึกษา นครสวรรค์ เขต 2
A5: ="ตำบล"&ข้อมูลพื้นฐาน!B5&" อำเภอ"&ข้อมูลพื้นฐาน!B6&" จังหวัด"&ข้อมูลพื้นฐาน!B7 -> ตำบลแม่วงก์ อำเภอแม่วงก์ จังหวัดนครสวรรค์
A6: ="ระดับชั้นประถมศึกษาปีที่ "&ข้อมูลพื้นฐาน!B9&" ปีการศึกษา "&ข้อมูลพื้นฐาน!B8 -> ระดับชั้นประถมศึกษาปีที่ ปีการศึกษา 2565
A7: ="ครูประจำชั้น "&ข้อมูลพื้นฐาน!B10 &" "&ข้อมูลพื้นฐาน!D10 -> ครูประจำชั้น
A8: ="ผู้อำนวยการโรงเรียน "&ข้อมูลพื้นฐาน!B11 -> ผู้อำนวยการโรงเรียน
H9: จำนวนนักเรียนที่ประเมินผลเมื่อสิ้นปีการศึกษา | Q9: ='กรอกข้อมูล นร1'!N60 -> #VALUE! | R9: คน
I10: จำนวนนักเรียนที่ผ่านการประเมิน | P10: =สรุปคะแนนทั้งปี!F354 | Q10: คน
A11: 1.รายวิชา | I11: จำนวนนักเรียนที่ได้ระดับผลการเรียน | S11: จำนวนผู้เรียนที่ผ่านเกณฑ์การประเมิน
I12: 4 | J12: 3.5 | K12: 3 | L12: 2.5 | M12: 2 | N12: 1.5 | O12: 1 | P12: 0 | Q12: ผ่าน | R12: ไม่ผ่าน | S12: ดีเยี่ยม | U12: ดี | W12: ผ่าน
A14: =ข้อมูลพื้นฐาน!A15 -> ภาษาไทย | I14: =IF(COUNTIF(สรุปคะแนนทั้งปี!$E$8:$E$57,"4"),COUNTIF(สรุปคะแนนทั้งปี!$E$8:$E$57,"4"),"-") -> - | J14: =IF(COUNTIF(สรุปคะแนนทั้งปี!$E$8:$E$57,"3.5"),COUNTIF(สรุปคะแนนทั้งปี!$E$8:$E$57,"3.5"),"-") -> - | K14: =IF(COUNTIF(สรุปคะแนนทั้งปี!$E$8:$E$57,"3"),COUNTIF(สรุปคะแนนทั้งปี!$E$8:$E$57,"3"),"-") -> - | L14: =IF(COUNTIF(สรุปคะแนนทั้งปี!$E$8:$E$57,"2.5"),COUNTIF(สรุปคะแนนทั้งปี!$E$8:$E$57,"2.5"),"-") -> - | M14: =IF(COUNTIF(สรุปคะแนนทั้งปี!$E$8:$E$57,"2"),COUNTIF(สรุปคะแนนทั้งปี!$E$8:$E$57,"2"),"-") -> - | N14: =IF(COUNTIF(สรุปคะแนนทั้งปี!$E$8:$E$57,"1.5"),COUNTIF(สรุปคะแนนทั้งปี!$E$8:$E$57,"1.5"),"-") -> - | O14: =IF(COUNTIF(สรุปคะแนนทั้งปี!$E$8:$E$57,"1"),COUNTIF(สรุปคะแนนทั้งปี!$E$8:$E$57,"1"),"-") -> - | P14: =IF(COUNTIF(สรุปคะแนนทั้งปี!$E$8:$E$57,"0"),COUNTIF(สรุปคะแนนทั้งปี!$E$8:$E$57,"0"),"-") -> 1 | Q14: =IF(SUM(I14:O14),SUM(I14:O14),"-") -> - | R14: =IF(SUM(P14),SUM(P14),"-") -> 1 | S14: - | U14: - | W14: -
A15: =ข้อมูลพื้นฐาน!A16 -> คณิตศาสตร์ | I15: =IF(COUNTIF(สรุปคะแนนทั้งปี!I8:I57,"4"),COUNTIF(สรุปคะแนนทั้งปี!I8:I57,"4"),"-") -> - | J15: =IF(COUNTIF(สรุปคะแนนทั้งปี!I8:I57,"3.5"),COUNTIF(สรุปคะแนนทั้งปี!I8:I57,"3.5"),"-") -> - | K15: =IF(COUNTIF(สรุปคะแนนทั้งปี!I8:I57,"3"),COUNTIF(สรุปคะแนนทั้งปี!I8:I57,"3"),"-") -> - | L15: =IF(COUNTIF(สรุปคะแนนทั้งปี!I8:I57,"2.5"),COUNTIF(สรุปคะแนนทั้งปี!I8:I57,"2.5"),"-") -> - | M15: =IF(COUNTIF(สรุปคะแนนทั้งปี!I8:I57,"2"),COUNTIF(สรุปคะแนนทั้งปี!I8:I57,"2"),"-") -> - | N15: =IF(COUNTIF(สรุปคะแนนทั้งปี!I8:I57,"1.5"),COUNTIF(สรุปคะแนนทั้งปี!I8:I57,"1.5"),"-") -> - | O15: =IF(COUNTIF(สรุปคะแนนทั้งปี!I8:I57,"1"),COUNTIF(สรุปคะแนนทั้งปี!I8:I57,"1"),"-") -> - | P15: =IF(COUNTIF(สรุปคะแนนทั้งปี!I8:I57,"0"),COUNTIF(สรุปคะแนนทั้งปี!I8:I57,"0"),"-") -> 1 | Q15: =IF(SUM(I15:O15),SUM(I15:O15),"-") -> - | R15: =IF(SUM(P15),SUM(P15),"-") -> 1 | S15: - | U15: - | W15: -
A16: =ข้อมูลพื้นฐาน!A17 -> วิทยาศาสตร์และเทคโนโลยี | I16: =IF(COUNTIF(สรุปคะแนนทั้งปี!M8:M57,"4"),COUNTIF(สรุปคะแนนทั้งปี!M8:M57,"4"),"-") -> - | J16: =IF(COUNTIF(สรุปคะแนนทั้งปี!M8:M57,"3.5"),COUNTIF(สรุปคะแนนทั้งปี!M8:M57,"3.5"),"-") -> - | K16: =IF(COUNTIF(สรุปคะแนนทั้งปี!M8:M57,"3"),COUNTIF(สรุปคะแนนทั้งปี!M8:M57,"3"),"-") -> - | L16: =IF(COUNTIF(สรุปคะแนนทั้งปี!M8:M57,"2.5"),COUNTIF(สรุปคะแนนทั้งปี!M8:M57,"2.5"),"-") -> - | M16: =IF(COUNTIF(สรุปคะแนนทั้งปี!M8:M57,"2"),COUNTIF(สรุปคะแนนทั้งปี!M8:M57,"2"),"-") -> - | N16: =IF(COUNTIF(สรุปคะแนนทั้งปี!M8:M57,"1.5"),COUNTIF(สรุปคะแนนทั้งปี!M8:M57,"1.5"),"-") -> - | O16: =IF(COUNTIF(สรุปคะแนนทั้งปี!M8:M57,"1"),COUNTIF(สรุปคะแนนทั้งปี!M8:M57,"1"),"-") -> - | P16: =IF(COUNTIF(สรุปคะแนนทั้งปี!M8:M57,"0"),COUNTIF(สรุปคะแนนทั้งปี!M8:M57,"0"),"-") -> 1 | Q16: =IF(SUM(I16:O16),SUM(I16:O16),"-") -> - | R16: =IF(SUM(P16),SUM(P16),"-") -> 1 | S16: - | U16: - | W16: -
A17: =ข้อมูลพื้นฐาน!A18 -> สังคมศึกษา ศาสนา และวัฒนธรรม | I17: =IF(COUNTIF(สรุปคะแนนทั้งปี!Q8:Q57,"4"),COUNTIF(สรุปคะแนนทั้งปี!Q8:Q57,"4"),"-") -> - | J17: =IF(COUNTIF(สรุปคะแนนทั้งปี!Q8:Q57,"3.5"),COUNTIF(สรุปคะแนนทั้งปี!Q8:Q57,"3.5"),"-") -> - | K17: =IF(COUNTIF(สรุปคะแนนทั้งปี!Q8:Q57,"3"),COUNTIF(สรุปคะแนนทั้งปี!Q8:Q57,"3"),"-") -> - | L17: =IF(COUNTIF(สรุปคะแนนทั้งปี!Q8:Q57,"2.5"),COUNTIF(สรุปคะแนนทั้งปี!Q8:Q57,"2.5"),"-") -> - | M17: =IF(COUNTIF(สรุปคะแนนทั้งปี!Q8:Q57,"2"),COUNTIF(สรุปคะแนนทั้งปี!Q8:Q57,"2"),"-") -> - | N17: =IF(COUNTIF(สรุปคะแนนทั้งปี!Q8:Q57,"1.5"),COUNTIF(สรุปคะแนนทั้งปี!Q8:Q57,"1.5"),"-") -> - | O17: =IF(COUNTIF(สรุปคะแนนทั้งปี!Q8:Q57,"1"),COUNTIF(สรุปคะแนนทั้งปี!Q8:Q57,"1"),"-") -> - | P17: =IF(COUNTIF(สรุปคะแนนทั้งปี!Q8:Q57,"0"),COUNTIF(สรุปคะแนนทั้งปี!Q8:Q57,"0"),"-") -> 1 | Q17: =IF(SUM(I17:O17),SUM(I17:O17),"-") -> - | R17: =IF(SUM(P17),SUM(P17),"-") -> 1 | S17: - | U17: - | W17: -
A18: =ข้อมูลพื้นฐาน!A19 -> ประวัติศาสตร์ | I18: =IF(COUNTIF(สรุปคะแนนทั้งปี!E68:E117,"4"),COUNTIF(สรุปคะแนนทั้งปี!E68:E117,"4"),"-") -> - | J18: =IF(COUNTIF(สรุปคะแนนทั้งปี!E68:E117,"3.5"),COUNTIF(สรุปคะแนนทั้งปี!E68:E117,"3.5"),"-") -> - | K18: =IF(COUNTIF(สรุปคะแนนทั้งปี!E68:E117,"3"),COUNTIF(สรุปคะแนนทั้งปี!E68:E117,"3"),"-") -> - | L18: =IF(COUNTIF(สรุปคะแนนทั้งปี!E68:E117,"2.5"),COUNTIF(สรุปคะแนนทั้งปี!E68:E117,"2.5"),"-") -> - | M18: =IF(COUNTIF(สรุปคะแนนทั้งปี!E68:E117,"2"),COUNTIF(สรุปคะแนนทั้งปี!E68:E117,"2"),"-") -> - | N18: =IF(COUNTIF(สรุปคะแนนทั้งปี!E68:E117,"1.5"),COUNTIF(สรุปคะแนนทั้งปี!E68:E117,"1.5"),"-") -> - | O18: =IF(COUNTIF(สรุปคะแนนทั้งปี!E68:E117,"1"),COUNTIF(สรุปคะแนนทั้งปี!E68:E117,"1"),"-") -> - | P18: =IF(COUNTIF(สรุปคะแนนทั้งปี!E68:E117,"0"),COUNTIF(สรุปคะแนนทั้งปี!E68:E117,"0"),"-") -> 1 | Q18: =IF(SUM(I18:O18),SUM(I18:O18),"-") -> - | R18: =IF(SUM(P18),SUM(P18),"-") -> 1 | S18: - | U18: - | W18: -
A19: =ข้อมูลพื้นฐาน!A20 -> สุขศึกษาและพลศึกษา | I19: =IF(COUNTIF(สรุปคะแนนทั้งปี!I68:I117,"4"),COUNTIF(สรุปคะแนนทั้งปี!I68:I117,"4"),"-") -> - | J19: =IF(COUNTIF(สรุปคะแนนทั้งปี!I68:I117,"3.5"),COUNTIF(สรุปคะแนนทั้งปี!I68:I117,"3.5"),"-") -> - | K19: =IF(COUNTIF(สรุปคะแนนทั้งปี!I68:I117,"3"),COUNTIF(สรุปคะแนนทั้งปี!I68:I117,"3"),"-") -> - | L19: =IF(COUNTIF(สรุปคะแนนทั้งปี!I68:I117,"2.5"),COUNTIF(สรุปคะแนนทั้งปี!I68:I117,"2.5"),"-") -> - | M19: =IF(COUNTIF(สรุปคะแนนทั้งปี!I68:I117,"2"),COUNTIF(สรุปคะแนนทั้งปี!I68:I117,"2"),"-") -> - | N19: =IF(COUNTIF(สรุปคะแนนทั้งปี!I68:I117,"1.5"),COUNTIF(สรุปคะแนนทั้งปี!I68:I117,"1.5"),"-") -> - | O19: =IF(COUNTIF(สรุปคะแนนทั้งปี!I68:I117,"1"),COUNTIF(สรุปคะแนนทั้งปี!I68:I117,"1"),"-") -> - | P19: =IF(COUNTIF(สรุปคะแนนทั้งปี!I68:I117,"0"),COUNTIF(สรุปคะแนนทั้งปี!I68:I117,"0"),"-") -> 1 | Q19: =IF(SUM(I19:O19),SUM(I19:O19),"-") -> - | R19: =IF(SUM(P19),SUM(P19),"-") -> 1 | S19: - | U19: - | W19: -
A20: =ข้อมูลพื้นฐาน!A21 -> ศิลปะ | I20: =IF(COUNTIF(สรุปคะแนนทั้งปี!M68:M117,"4"),COUNTIF(สรุปคะแนนทั้งปี!M68:M117,"4"),"-") -> - | J20: =IF(COUNTIF(สรุปคะแนนทั้งปี!M68:M117,"3.5"),COUNTIF(สรุปคะแนนทั้งปี!M68:M117,"3.5"),"-") -> - | K20: =IF(COUNTIF(สรุปคะแนนทั้งปี!M68:M117,"3"),COUNTIF(สรุปคะแนนทั้งปี!M68:M117,"3"),"-") -> - | L20: =IF(COUNTIF(สรุปคะแนนทั้งปี!M68:M117,"2.5"),COUNTIF(สรุปคะแนนทั้งปี!M68:M117,"2.5"),"-") -> - | M20: =IF(COUNTIF(สรุปคะแนนทั้งปี!M68:M117,"2"),COUNTIF(สรุปคะแนนทั้งปี!M68:M117,"2"),"-") -> - | N20: =IF(COUNTIF(สรุปคะแนนทั้งปี!M68:M117,"1.5"),COUNTIF(สรุปคะแนนทั้งปี!M68:M117,"1.5"),"-") -> - | O20: =IF(COUNTIF(สรุปคะแนนทั้งปี!M68:M117,"1"),COUNTIF(สรุปคะแนนทั้งปี!M68:M117,"1"),"-") -> - | P20: =IF(COUNTIF(สรุปคะแนนทั้งปี!M68:M117,"0"),COUNTIF(สรุปคะแนนทั้งปี!M68:M117,"0"),"-") -> 1 | Q20: =IF(SUM(I20:O20),SUM(I20:O20),"-") -> - | R20: =IF(SUM(P20),SUM(P20),"-") -> 1 | S20: - | U20: - | W20: -
A21: =ข้อมูลพื้นฐาน!A22 -> การงานอาชีพ | I21: =IF(COUNTIF(สรุปคะแนนทั้งปี!Q68:Q117,"4"),COUNTIF(สรุปคะแนนทั้งปี!Q68:Q117,"4"),"-") -> - | J21: =IF(COUNTIF(สรุปคะแนนทั้งปี!Q68:Q117,"3.5"),COUNTIF(สรุปคะแนนทั้งปี!Q68:Q117,"3.5"),"-") -> - | K21: =IF(COUNTIF(สรุปคะแนนทั้งปี!Q68:Q117,"3"),COUNTIF(สรุปคะแนนทั้งปี!Q68:Q117,"3"),"-") -> - | L21: =IF(COUNTIF(สรุปคะแนนทั้งปี!Q68:Q117,"2.5"),COUNTIF(สรุปคะแนนทั้งปี!Q68:Q117,"2.5"),"-") -> - | M21: =IF(COUNTIF(สรุปคะแนนทั้งปี!Q68:Q117,"2"),COUNTIF(สรุปคะแนนทั้งปี!Q68:Q117,"2"),"-") -> - | N21: =IF(COUNTIF(สรุปคะแนนทั้งปี!Q68:Q117,"1.5"),COUNTIF(สรุปคะแนนทั้งปี!Q68:Q117,"1.5"),"-") -> - | O21: =IF(COUNTIF(สรุปคะแนนทั้งปี!Q68:Q117,"1"),COUNTIF(สรุปคะแนนทั้งปี!Q68:Q117,"1"),"-") -> - | P21: =IF(COUNTIF(สรุปคะแนนทั้งปี!Q68:Q117,"0"),COUNTIF(สรุปคะแนนทั้งปี!Q68:Q117,"0"),"-") -> 1 | Q21: =IF(SUM(I21:O21),SUM(I21:O21),"-") -> - | R21: =IF(SUM(P21),SUM(P21),"-") -> 1 | S21: - | U21: - | W21: -
A22: =ข้อมูลพื้นฐาน!A23 -> ภาษาอังกฤษ | I22: =IF(COUNTIF(สรุปคะแนนทั้งปี!E128:E177,"4"),COUNTIF(สรุปคะแนนทั้งปี!E128:E177,"4"),"-") -> - | J22: =IF(COUNTIF(สรุปคะแนนทั้งปี!E128:E177,"3.5"),COUNTIF(สรุปคะแนนทั้งปี!E128:E177,"3.5"),"-") -> - | K22: =IF(COUNTIF(สรุปคะแนนทั้งปี!E128:E177,"3"),COUNTIF(สรุปคะแนนทั้งปี!E128:E177,"3"),"-") -> - | L22: =IF(COUNTIF(สรุปคะแนนทั้งปี!E128:E177,"2.5"),COUNTIF(สรุปคะแนนทั้งปี!E128:E177,"2.5"),"-") -> - | M22: =IF(COUNTIF(สรุปคะแนนทั้งปี!E128:E177,"2"),COUNTIF(สรุปคะแนนทั้งปี!E128:E177,"2"),"-") -> - | N22: =IF(COUNTIF(สรุปคะแนนทั้งปี!E128:E177,"1.5"),COUNTIF(สรุปคะแนนทั้งปี!E128:E177,"1.5"),"-") -> - | O22: =IF(COUNTIF(สรุปคะแนนทั้งปี!E128:E177,"1"),COUNTIF(สรุปคะแนนทั้งปี!E128:E177,"1"),"-") -> - | P22: =IF(COUNTIF(สรุปคะแนนทั้งปี!E128:E177,"0"),COUNTIF(สรุปคะแนนทั้งปี!E128:E177,"0"),"-") -> 1 | Q22: =IF(SUM(I22:O22),SUM(I22:O22),"-") -> - | R22: =IF(SUM(P22),SUM(P22),"-") -> 1 | S22: - | U22: - | W22: -
A23: รายวิชาเพิ่มเติม
A24: =ข้อมูลพื้นฐาน!A25&"" -> ภาษาอังกฤษเพื่อการสื่อสาร | I24: =IF(COUNTIF(สรุปคะแนนทั้งปี!I128:I177,"4"),COUNTIF(สรุปคะแนนทั้งปี!I128:I177,"4"),"-") -> - | J24: =IF(COUNTIF(สรุปคะแนนทั้งปี!I128:I177,"3.5"),COUNTIF(สรุปคะแนนทั้งปี!I128:I177,"3.5"),"-") -> - | K24: =IF(COUNTIF(สรุปคะแนนทั้งปี!I128:I177,"3"),COUNTIF(สรุปคะแนนทั้งปี!I128:I177,"3"),"-") -> - | L24: =IF(COUNTIF(สรุปคะแนนทั้งปี!I128:I177,"2.5"),COUNTIF(สรุปคะแนนทั้งปี!I128:I177,"2.5"),"-") -> - | M24: =IF(COUNTIF(สรุปคะแนนทั้งปี!I128:I177,"2"),COUNTIF(สรุปคะแนนทั้งปี!I128:I177,"2"),"-") -> - | N24: =IF(COUNTIF(สรุปคะแนนทั้งปี!I128:I177,"1.5"),COUNTIF(สรุปคะแนนทั้งปี!I128:I177,"1.5"),"-") -> - | O24: =IF(COUNTIF(สรุปคะแนนทั้งปี!I128:I177,"1"),COUNTIF(สรุปคะแนนทั้งปี!I128:I177,"1"),"-") -> - | P24: =IF(COUNTIF(สรุปคะแนนทั้งปี!I128:I177,"0"),COUNTIF(สรุปคะแนนทั้งปี!I128:I177,"0"),"-") -> 1 | Q24: =IF(SUM(I24:O24),SUM(I24:O24),"-") -> - | R24: =IF(SUM(P24),SUM(P24),"-") -> 1 | S24: - | U24: - | W24: -
A25: =ข้อมูลพื้นฐาน!A26&"" | I25: =IF(COUNTIF(สรุปคะแนนทั้งปี!M128:M177,"4"),COUNTIF(สรุปคะแนนทั้งปี!M128:M177,"4"),"-") -> - | J25: =IF(COUNTIF(สรุปคะแนนทั้งปี!M128:M177,"3.5"),COUNTIF(สรุปคะแนนทั้งปี!M128:M177,"3.5"),"-") -> - | K25: =IF(COUNTIF(สรุปคะแนนทั้งปี!M128:M177,"3"),COUNTIF(สรุปคะแนนทั้งปี!M128:M177,"3"),"-") -> - | L25: =IF(COUNTIF(สรุปคะแนนทั้งปี!M128:M177,"2.5"),COUNTIF(สรุปคะแนนทั้งปี!M128:M177,"2.5"),"-") -> - | M25: =IF(COUNTIF(สรุปคะแนนทั้งปี!M128:M177,"2"),COUNTIF(สรุปคะแนนทั้งปี!M128:M177,"2"),"-") -> - | N25: =IF(COUNTIF(สรุปคะแนนทั้งปี!M128:M177,"1.5"),COUNTIF(สรุปคะแนนทั้งปี!M128:M177,"1.5"),"-") -> - | O25: =IF(COUNTIF(สรุปคะแนนทั้งปี!M128:M177,"1"),COUNTIF(สรุปคะแนนทั้งปี!M128:M177,"1"),"-") -> - | P25: =IF(COUNTIF(สรุปคะแนนทั้งปี!M128:M177,"0"),COUNTIF(สรุปคะแนนทั้งปี!M128:M177,"0"),"-") -> - | Q25: =IF(SUM(I25:O25),SUM(I25:O25),"-") -> - | R25: =IF(SUM(P25),SUM(P25),"-") -> - | S25: - | U25: - | W25: -
A26: =ข้อมูลพื้นฐาน!A27&"" | I26: =IF(COUNTIF(สรุปคะแนนทั้งปี!Q128:Q177,"4"),COUNTIF(สรุปคะแนนทั้งปี!Q128:Q177,"4"),"-") -> - | J26: =IF(COUNTIF(สรุปคะแนนทั้งปี!Q128:Q177,"3.5"),COUNTIF(สรุปคะแนนทั้งปี!Q128:Q177,"3.5"),"-") -> - | K26: =IF(COUNTIF(สรุปคะแนนทั้งปี!Q128:Q177,"3"),COUNTIF(สรุปคะแนนทั้งปี!Q128:Q177,"3"),"-") -> - | L26: =IF(COUNTIF(สรุปคะแนนทั้งปี!Q128:Q177,"2.5"),COUNTIF(สรุปคะแนนทั้งปี!Q128:Q177,"2.5"),"-") -> - | M26: =IF(COUNTIF(สรุปคะแนนทั้งปี!Q128:Q177,"2"),COUNTIF(สรุปคะแนนทั้งปี!Q128:Q177,"2"),"-") -> - | N26: =IF(COUNTIF(สรุปคะแนนทั้งปี!Q128:Q177,"1.5"),COUNTIF(สรุปคะแนนทั้งปี!Q128:Q177,"1.5"),"-") -> - | O26: =IF(COUNTIF(สรุปคะแนนทั้งปี!Q128:Q177,"1"),COUNTIF(สรุปคะแนนทั้งปี!Q128:Q177,"1"),"-") -> - | P26: =IF(COUNTIF(สรุปคะแนนทั้งปี!Q128:Q177,"0"),COUNTIF(สรุปคะแนนทั้งปี!Q128:Q177,"0"),"-") -> - | Q26: =IF(SUM(I26:O26),SUM(I26:O26),"-") -> - | R26: =IF(SUM(P26),SUM(P26),"-") -> - | S26: - | U26: - | W26: -
A27: =ข้อมูลพื้นฐาน!A28&"" | I27: =IF(COUNTIF(สรุปคะแนนทั้งปี!E189:E238,"4"),COUNTIF(สรุปคะแนนทั้งปี!E189:E238,"4"),"-") -> - | J27: =IF(COUNTIF(สรุปคะแนนทั้งปี!E189:E238,"3.5"),COUNTIF(สรุปคะแนนทั้งปี!E189:E238,"3.5"),"-") -> - | K27: =IF(COUNTIF(สรุปคะแนนทั้งปี!E189:E238,"3"),COUNTIF(สรุปคะแนนทั้งปี!E189:E238,"3"),"-") -> - | L27: =IF(COUNTIF(สรุปคะแนนทั้งปี!E189:E238,"2.5"),COUNTIF(สรุปคะแนนทั้งปี!E189:E238,"2.5"),"-") -> - | M27: =IF(COUNTIF(สรุปคะแนนทั้งปี!E189:E238,"2"),COUNTIF(สรุปคะแนนทั้งปี!E189:E238,"2"),"-") -> - | N27: =IF(COUNTIF(สรุปคะแนนทั้งปี!E189:E238,"1.5"),COUNTIF(สรุปคะแนนทั้งปี!E189:E238,"1.5"),"-") -> - | O27: =IF(COUNTIF(สรุปคะแนนทั้งปี!E189:E238,"1"),COUNTIF(สรุปคะแนนทั้งปี!E189:E238,"1"),"-") -> - | P27: =IF(COUNTIF(สรุปคะแนนทั้งปี!E189:E238,"0"),COUNTIF(สรุปคะแนนทั้งปี!E189:E238,"0"),"-") -> - | Q27: =IF(SUM(I27:O27),SUM(I27:O27),"-") -> - | R27: =IF(SUM(P27),SUM(P27),"-") -> - | S27: - | U27: - | W27: -
A28: =ข้อมูลพื้นฐาน!A29&"" | I28: =IF(COUNTIF(สรุปคะแนนทั้งปี!I189:I238,"4"),COUNTIF(สรุปคะแนนทั้งปี!I189:I238,"4"),"-") -> - | J28: =IF(COUNTIF(สรุปคะแนนทั้งปี!I189:I238,"3.5"),COUNTIF(สรุปคะแนนทั้งปี!I189:I238,"3.5"),"-") -> - | K28: =IF(COUNTIF(สรุปคะแนนทั้งปี!I189:I238,"3"),COUNTIF(สรุปคะแนนทั้งปี!I189:I238,"3"),"-") -> - | L28: =IF(COUNTIF(สรุปคะแนนทั้งปี!I189:I238,"2.5"),COUNTIF(สรุปคะแนนทั้งปี!I189:I238,"2.5"),"-") -> - | M28: =IF(COUNTIF(สรุปคะแนนทั้งปี!I189:I238,"2"),COUNTIF(สรุปคะแนนทั้งปี!I189:I238,"2"),"-") -> - | N28: =IF(COUNTIF(สรุปคะแนนทั้งปี!I189:I238,"1.5"),COUNTIF(สรุปคะแนนทั้งปี!I189:I238,"1.5"),"-") -> - | O28: =IF(COUNTIF(สรุปคะแนนทั้งปี!I189:I238,"1"),COUNTIF(สรุปคะแนนทั้งปี!I189:I238,"1"),"-") -> - | P28: =IF(COUNTIF(สรุปคะแนนทั้งปี!I189:I238,"0"),COUNTIF(สรุปคะแนนทั้งปี!I189:I238,"0"),"-") -> - | Q28: =IF(SUM(I28:O28),SUM(I28:O28),"-") -> - | R28: =IF(SUM(P28),SUM(P28),"-") -> - | S28: - | U28: - | W28: -
A29: =ข้อมูลพื้นฐาน!A30&"" | I29: =IF(COUNTIF(สรุปคะแนนทั้งปี!M189:M238,"4"),COUNTIF(สรุปคะแนนทั้งปี!M189:M238,"4"),"-") -> - | J29: =IF(COUNTIF(สรุปคะแนนทั้งปี!M189:M238,"3.5"),COUNTIF(สรุปคะแนนทั้งปี!M189:M238,"3.5"),"-") -> - | K29: =IF(COUNTIF(สรุปคะแนนทั้งปี!M189:M238,"3"),COUNTIF(สรุปคะแนนทั้งปี!M189:M238,"3"),"-") -> - | L29: =IF(COUNTIF(สรุปคะแนนทั้งปี!M189:M238,"2.5"),COUNTIF(สรุปคะแนนทั้งปี!M189:M238,"2.5"),"-") -> - | M29: =IF(COUNTIF(สรุปคะแนนทั้งปี!M189:M238,"2"),COUNTIF(สรุปคะแนนทั้งปี!M189:M238,"2"),"-") -> - | N29: =IF(COUNTIF(สรุปคะแนนทั้งปี!M189:M238,"1.5"),COUNTIF(สรุปคะแนนทั้งปี!M189:M238,"1.5"),"-") -> - | O29: =IF(COUNTIF(สรุปคะแนนทั้งปี!M189:M238,"1"),COUNTIF(สรุปคะแนนทั้งปี!M189:M238,"1"),"-") -> - | P29: =IF(COUNTIF(สรุปคะแนนทั้งปี!M189:M238,"0"),COUNTIF(สรุปคะแนนทั้งปี!M189:M238,"0"),"-") -> - | Q29: =IF(SUM(I29:O29),SUM(I29:O29),"-") -> - | R29: =IF(SUM(P29),SUM(P29),"-") -> - | S29: - | U29: - | W29: -
A30: =ข้อมูลพื้นฐาน!A31&"" | I30: =IF(COUNTIF(สรุปคะแนนทั้งปี!Q189:Q238,"4"),COUNTIF(สรุปคะแนนทั้งปี!Q189:Q238,"4"),"-") -> - | J30: =IF(COUNTIF(สรุปคะแนนทั้งปี!Q189:Q238,"3.5"),COUNTIF(สรุปคะแนนทั้งปี!Q189:Q238,"3.5"),"-") -> - | K30: =IF(COUNTIF(สรุปคะแนนทั้งปี!Q189:Q238,"3"),COUNTIF(สรุปคะแนนทั้งปี!Q189:Q238,"3"),"-") -> - | L30: =IF(COUNTIF(สรุปคะแนนทั้งปี!Q189:Q238,"2.5"),COUNTIF(สรุปคะแนนทั้งปี!Q189:Q238,"2.5"),"-") -> - | M30: =IF(COUNTIF(สรุปคะแนนทั้งปี!Q189:Q238,"2"),COUNTIF(สรุปคะแนนทั้งปี!Q189:Q238,"2"),"-") -> - | N30: =IF(COUNTIF(สรุปคะแนนทั้งปี!Q189:Q238,"1.5"),COUNTIF(สรุปคะแนนทั้งปี!Q189:Q238,"1.5"),"-") -> - | O30: =IF(COUNTIF(สรุปคะแนนทั้งปี!Q189:Q238,"1"),COUNTIF(สรุปคะแนนทั้งปี!Q189:Q238,"1"),"-") -> - | P30: =IF(COUNTIF(สรุปคะแนนทั้งปี!Q189:Q238,"0"),COUNTIF(สรุปคะแนนทั้งปี!Q189:Q238,"0"),"-") -> - | Q30: =IF(SUM(I30:O30),SUM(I30:O30),"-") -> - | R30: =IF(SUM(P30),SUM(P30),"-") -> - | S30: - | U30: - | W30: -
A31: =ข้อมูลพื้นฐาน!A32&"" | I31: =IF(COUNTIF(สรุปคะแนนทั้งปี!E247:E296,"4"),COUNTIF(สรุปคะแนนทั้งปี!E247:E296,"4"),"-") -> - | J31: =IF(COUNTIF(สรุปคะแนนทั้งปี!E247:E296,"3.5"),COUNTIF(สรุปคะแนนทั้งปี!E247:E296,"4"),"-") -> - | K31: =IF(COUNTIF(สรุปคะแนนทั้งปี!E247:E296,"3"),COUNTIF(สรุปคะแนนทั้งปี!E247:E296,"3"),"-") -> - | L31: =IF(COUNTIF(สรุปคะแนนทั้งปี!E247:E296,"2.5"),COUNTIF(สรุปคะแนนทั้งปี!E247:E296,"2.5"),"-") -> - | M31: =IF(COUNTIF(สรุปคะแนนทั้งปี!E247:E296,"2"),COUNTIF(สรุปคะแนนทั้งปี!E247:E296,"2"),"-") -> - | N31: =IF(COUNTIF(สรุปคะแนนทั้งปี!E247:E296,"1.5"),COUNTIF(สรุปคะแนนทั้งปี!E247:E296,"1.5"),"-") -> - | O31: =IF(COUNTIF(สรุปคะแนนทั้งปี!E247:E296,"1"),COUNTIF(สรุปคะแนนทั้งปี!E247:E296,"1"),"-") -> - | P31: =IF(COUNTIF(สรุปคะแนนทั้งปี!E247:E296,"0"),COUNTIF(สรุปคะแนนทั้งปี!E247:E296,"0"),"-") -> - | Q31: =IF(SUM(I31:O31),SUM(I31:O31),"-") -> - | R31: =IF(SUM(P31),SUM(P31),"-") -> - | S31: - | U31: - | W31: -
A32: =ข้อมูลพื้นฐาน!A33&"" | I32: =IF(COUNTIF(สรุปคะแนนทั้งปี!I247:I296,"4"),COUNTIF(สรุปคะแนนทั้งปี!I247:I296,"4"),"-") -> - | J32: =IF(COUNTIF(สรุปคะแนนทั้งปี!I247:I296,"3.5"),COUNTIF(สรุปคะแนนทั้งปี!I247:I296,"3.5"),"-") -> - | K32: =IF(COUNTIF(สรุปคะแนนทั้งปี!I247:I296,"3"),COUNTIF(สรุปคะแนนทั้งปี!I247:I296,"3"),"-") -> - | L32: =IF(COUNTIF(สรุปคะแนนทั้งปี!I247:I296,"2.5"),COUNTIF(สรุปคะแนนทั้งปี!I247:I296,"2.5"),"-") -> - | M32: =IF(COUNTIF(สรุปคะแนนทั้งปี!I247:I296,"2"),COUNTIF(สรุปคะแนนทั้งปี!I247:I296,"2"),"-") -> - | N32: =IF(COUNTIF(สรุปคะแนนทั้งปี!I247:I296,"1.5"),COUNTIF(สรุปคะแนนทั้งปี!I247:I296,"1.5"),"-") -> - | O32: =IF(COUNTIF(สรุปคะแนนทั้งปี!I247:I296,"1"),COUNTIF(สรุปคะแนนทั้งปี!I247:I296,"1"),"-") -> - | P32: =IF(COUNTIF(สรุปคะแนนทั้งปี!I247:I296,"0"),COUNTIF(สรุปคะแนนทั้งปี!I247:I296,"0"),"-") -> - | Q32: =IF(SUM(I32:O32),SUM(I32:O32),"-") -> - | R32: =IF(SUM(P32),SUM(P32),"-") -> - | S32: - | U32: - | W32: -
A33: =ข้อมูลพื้นฐาน!A34&"" | I33: =IF(COUNTIF(สรุปคะแนนทั้งปี!M247:M296,"4"),COUNTIF(สรุปคะแนนทั้งปี!M247:M296,"4"),"-") -> - | J33: =IF(COUNTIF(สรุปคะแนนทั้งปี!M247:M296,"3.5"),COUNTIF(สรุปคะแนนทั้งปี!M247:M296,"3.5"),"-") -> - | K33: =IF(COUNTIF(สรุปคะแนนทั้งปี!M247:M296,"3"),COUNTIF(สรุปคะแนนทั้งปี!M247:M296,"3"),"-") -> - | L33: =IF(COUNTIF(สรุปคะแนนทั้งปี!M247:M296,"2.5"),COUNTIF(สรุปคะแนนทั้งปี!M247:M296,"2.5"),"-") -> - | M33: =IF(COUNTIF(สรุปคะแนนทั้งปี!M247:M296,"2"),COUNTIF(สรุปคะแนนทั้งปี!M247:M296,"2"),"-") -> - | N33: =IF(COUNTIF(สรุปคะแนนทั้งปี!M247:M296,"1.5"),COUNTIF(สรุปคะแนนทั้งปี!M247:M296,"1.5"),"-") -> - | O33: =IF(COUNTIF(สรุปคะแนนทั้งปี!M247:M296,"1"),COUNTIF(สรุปคะแนนทั้งปี!M247:M296,"1"),"-") -> - | P33: =IF(COUNTIF(สรุปคะแนนทั้งปี!M247:M296,"0"),COUNTIF(สรุปคะแนนทั้งปี!M247:M296,"0"),"-") -> - | Q33: =IF(SUM(I33:O33),SUM(I33:O33),"-") -> - | R33: =IF(SUM(P33),SUM(P33),"-") -> - | S33: - | U33: - | W33: -
A34: =ข้อมูลพื้นฐาน!A35&"" | I34: =IF(COUNTIF(สรุปคะแนนทั้งปี!Q247:Q296,"4"),COUNTIF(สรุปคะแนนทั้งปี!Q247:Q296,"4"),"-") -> - | J34: =IF(COUNTIF(สรุปคะแนนทั้งปี!Q247:Q296,"3.5"),COUNTIF(สรุปคะแนนทั้งปี!Q247:Q296,"3.5"),"-") -> - | K34: =IF(COUNTIF(สรุปคะแนนทั้งปี!Q247:Q296,"3"),COUNTIF(สรุปคะแนนทั้งปี!Q247:Q296,"3"),"-") -> - | L34: =IF(COUNTIF(สรุปคะแนนทั้งปี!Q247:Q296,"2.5"),COUNTIF(สรุปคะแนนทั้งปี!Q247:Q296,"2.5"),"-") -> - | M34: =IF(COUNTIF(สรุปคะแนนทั้งปี!Q247:Q296,"2"),COUNTIF(สรุปคะแนนทั้งปี!Q247:Q296,"2"),"-") -> - | N34: =IF(COUNTIF(สรุปคะแนนทั้งปี!Q247:Q296,"1.5"),COUNTIF(สรุปคะแนนทั้งปี!Q247:Q296,"1.5"),"-") -> - | O34: =IF(COUNTIF(สรุปคะแนนทั้งปี!Q247:Q296,"1"),COUNTIF(สรุปคะแนนทั้งปี!Q247:Q296,"1"),"-") -> - | P34: =IF(COUNTIF(สรุปคะแนนทั้งปี!Q247:Q296,"0"),COUNTIF(สรุปคะแนนทั้งปี!Q247:Q296,"0"),"-") -> - | Q34: =IF(SUM(I34:O34),SUM(I34:O34),"-") -> - | R34: =IF(SUM(P34),SUM(P34),"-") -> - | S34: - | U34: - | W34: -
A35: =ข้อมูลพื้นฐาน!A36&"" | I35: =IF(COUNTIF(สรุปคะแนนทั้งปี!E304:E353,"4"),COUNTIF(สรุปคะแนนทั้งปี!E304:E353,"4"),"-") -> - | J35: =IF(COUNTIF(สรุปคะแนนทั้งปี!E304:E353,"3.5"),COUNTIF(สรุปคะแนนทั้งปี!E304:E353,"3.5"),"-") -> - | K35: =IF(COUNTIF(สรุปคะแนนทั้งปี!E304:E353,"3"),COUNTIF(สรุปคะแนนทั้งปี!E304:E353,"3"),"-") -> - | L35: =IF(COUNTIF(สรุปคะแนนทั้งปี!E304:E353,"2.5"),COUNTIF(สรุปคะแนนทั้งปี!E304:E353,"2.5"),"-") -> - | M35: =IF(COUNTIF(สรุปคะแนนทั้งปี!E304:E353,"2"),COUNTIF(สรุปคะแนนทั้งปี!E304:E353,"2"),"-") -> - | N35: =IF(COUNTIF(สรุปคะแนนทั้งปี!E304:E353,"1.5"),COUNTIF(สรุปคะแนนทั้งปี!E304:E353,"1.5"),"-") -> - | O35: =IF(COUNTIF(สรุปคะแนนทั้งปี!E304:E353,"1"),COUNTIF(สรุปคะแนนทั้งปี!E304:E353,"1"),"-") -> - | P35: =IF(COUNTIF(สรุปคะแนนทั้งปี!E304:E353,"0"),COUNTIF(สรุปคะแนนทั้งปี!E304:E353,"0"),"-") -> - | Q35: =IF(SUM(I35:O35),SUM(I35:O35),"-") -> - | R35: =IF(SUM(P35),SUM(P35),"-") -> - | S35: - | U35: - | W35: -
A36: 2. กิจกรรมพัฒนาผู้เรียน | I36: กิจกรรมแนะแนว | Q36: =IF(COUNTIF(กิจกรรมพัฒนผู้เรียน!C6:C55,"ผ"),COUNTIF(กิจกรรมพัฒนผู้เรียน!C6:C55,"ผ"),"") -> 1 | R36: =IF(COUNTIF(กิจกรรมพัฒนผู้เรียน!C6:C55,"มผ"),COUNTIF(กิจกรรมพัฒนผู้เรียน!C6:C55,"มผ"),"-") -> - | S36: - | U36: - | W36: -
I37: กิจกรรมนักเรียน | M37: - ลูกเสือ | Q37: =IF(COUNTIF(กิจกรรมพัฒนผู้เรียน!F6:F55,"ผ"),COUNTIF(กิจกรรมพัฒนผู้เรียน!F6:F55,"ผ"),"") -> 1 | R37: =IF(COUNTIF(กิจกรรมพัฒนผู้เรียน!F6:F55,"มผ"),COUNTIF(กิจกรรมพัฒนผู้เรียน!F6:F55,"มผ"),"-") -> - | S37: - | U37: - | W37: -
M38: - ชุมนุม | Q38: =IF(COUNTIF(กิจกรรมพัฒนผู้เรียน!I6:I55,"ผ"),COUNTIF(กิจกรรมพัฒนผู้เรียน!I6:I55,"ผ"),"") -> 1 | R38: =IF(COUNTIF(กิจกรรมพัฒนผู้เรียน!I6:I55,"มผ"),COUNTIF(กิจกรรมพัฒนผู้เรียน!I6:I55,"มผ"),"-") -> - | S38: - | U38: - | W38: -
I39: กิจกรรมเพื่อสังคมและสาธารณประโยชน์ | Q39: =IF(COUNTIF(กิจกรรมพัฒนผู้เรียน!U6:V55,"ผ"),COUNTIF(กิจกรรมพัฒนผู้เรียน!U6:V55,"ผ"),"") -> 1 | R39: =IF(COUNTIF(กิจกรรมพัฒนผู้เรียน!U6:V55,"มผ"),COUNTIF(กิจกรรมพัฒนผู้เรียน!U6:V55,"มผ"),"-") -> - | S39: - | U39: - | W39: -
A40: 3.คุณลักษณะอันพึงประสงค์ | Q40: =SUM(S40:X40) -> 0 | R40: =IF(COUNTIF(คุณลักษณะอันพึงประสงค์!V8:V57,"มผ"),COUNTIF(คุณลักษณะอันพึงประสงค์!V8:V57,"มผ"),"-") -> - | S40: =IF(COUNTIF(คุณลักษณะอันพึงประสงค์!V8:V57,""),COUNTIF(คุณลักษณะอันพึงประสงค์!V8:V57,"ดย"),"-") -> 0 | U40: =IF(COUNTIF(คุณลักษณะอันพึงประสงค์!V8:V57,"ด"),COUNTIF(คุณลักษณะอันพึงประสงค์!V8:V57,"ด"),"-") -> - | W40: =IF(COUNTIF(คุณลักษณะอันพึงประสงค์!V8:V57,"ผ"),COUNTIF(คุณลักษณะอันพึงประสงค์!V8:V57,"ผ"),"-") -> -
A41: 4.การอ่าน คิด วิเคราะห์ และเขียน | Q41: =SUM(S41:X41) -> 0 | R41: =IF(COUNTIF('อ่าน คิดวิเคราะห์ เขียน'!I6:I55,"มผ"),COUNTIF('อ่าน คิดวิเคราะห์ เขียน'!I6:I55,"มผ"),"-") -> - | S41: =IF(COUNTIF('อ่าน คิดวิเคราะห์ เขียน'!I6:I55,"ดย"),COUNTIF('อ่าน คิดวิเคราะห์ เขียน'!I6:I55,"ดย"),"-") -> - | U41: =IF(COUNTIF('อ่าน คิดวิเคราะห์ เขียน'!I6:I55,"ด"),COUNTIF('อ่าน คิดวิเคราะห์ เขียน'!I6:I55,"ด"),"-") -> - | W41: =IF(COUNTIF('อ่าน คิดวิเคราะห์ เขียน'!I6:I55,"ผ"),COUNTIF('อ่าน คิดวิเคราะห์ เขียน'!I6:I55,"ผ"),"-") -> -
A42: 5.สมรรถนะผู้เรียน | Q42: =SUM(S42:X42) -> 0 | R42: =IF(COUNTIF(สมรรถนะ!I5:I54,"มผ"),COUNTIF(สมรรถนะ!I5:I54,"มผ"),"-") -> - | S42: =IF(COUNTIF(สมรรถนะ!I5:I54,"ดย"),COUNTIF(สมรรถนะ!I5:I54,"ดย"),"-") -> - | U42: =IF(COUNTIF(สมรรถนะ!I5:I54,"ด"),COUNTIF(สมรรถนะ!I5:I54,"ด"),"-") -> - | W42: =IF(COUNTIF(สมรรถนะ!I5:I54,"ผ"),COUNTIF(สมรรถนะ!I5:I54,"ผ"),"-") -> -
...

Sheet เวลาเรียน1
A2: เลขที่ | B2: เลขประจำตัว | C2: เลขประจำตัวประชาชน | D2: ชื่อ - สกุล | E2: ปี | F2: 2565 | Z2: =F2 -> 2565 | BI2: =F2 -> 2565 | CR2: =F2 -> 2565 | EA2: =F2 -> 2565 | FJ2: =F2 -> 2565
E3: เดือน | F3: พฤษภาคม | V3: รวม | Z3: มิถุนายน | BE3: รวม | BI3: กรกฏาคม | CN3: รวม | CR3: สิงหาคม | DW3: รวม | EA3: กันยายน | FF3: รวม | FJ3: ตุลาคม | GO3: รวม | GS3: รวมทั้งเทอม | GW3: รวม
E5: วันที่/เต็ม | V5: มา | W5: ป่วย | X5: ลา | Y5: ขาด | BE5: มา | BF5: ป่วย | BG5: ลา | BH5: ขาด | CN5: มา | CO5: ป่วย | CP5: ลา | CQ5: ขาด | DW5: มา | DX5: ป่วย | DY5: ลา | DZ5: ขาด | FF5: มา | FG5: ป่วย | FH5: ลา | FI5: ขาด | GO5: มา | GP5: ป่วย | GQ5: ลา | GR5: ขาด | GS5: มา | GT5: ป่วย | GU5: ลา | GV5: ขาด
E6: 100 | F6: 16 | G6: 17 | H6: 18 | I6: 19 | J6: 20 | K6: 21 | L6: 22 | M6: 23 | N6: 24 | O6: 25 | P6: 26 | Q6: 27 | R6: 28 | S6: 29 | T6: 30 | U6: 31 | Z6: 1 | AA6: 2 | AB6: 3 | AC6: 4 | AD6: 5 | AE6: 6 | AF6: 7 | AG6: 8 | AH6: 9 | AI6: 10 | AJ6: 11 | AK6: 12 | AL6: 13 | AM6: 14 | AN6: 15 | AO6: 16 | AP6: 17 | AQ6: 18 | AR6: 19 | AS6: 20 | AT6: 21 | AU6: 22 | AV6: 23 | AW6: 24 | AX6: 25 | AY6: 26 | AZ6: 27 | BA6: 28 | BB6: 29 | BC6: 30 | BI6: 1 | BJ6: 2 | BK6: 3 | BL6: 4 | BM6: 5 | BN6: 6 | BO6: 7 | BP6: 8 | BQ6: 9 | BR6: 10 | BS6: 11 | BT6: 12 | BU6: 13 | BV6: 14 | BW6: 15 | BX6: 16 | BY6: 17 | BZ6: 18 | CA6: 19 | CB6: 20 | CC6: 21 | CD6: 22 | CE6: 23 | CF6: 24 | CG6: 25 | CH6: 26 | CI6: 27 | CJ6: 28 | CK6: 29 | CL6: 30 | CM6: 31 | CR6: 1 | CS6: 2 | CT6: 3 | CU6: 4 | CV6: 5 | CW6: 6 | CX6: 7 | CY6: 8 | CZ6: 9 | DA6: 10 | DB6: 11 | DC6: 12 | DD6: 13 | DE6: 14 | DF6: 15 | DG6: 16 | DH6: 17 | DI6: 18 | DJ6: 19 | DK6: 20 | DL6: 21 | DM6: 22 | DN6: 23 | DO6: 24 | DP6: 25 | DQ6: 26 | DR6: 27 | DS6: 28 | DT6: 29 | DU6: 30 | DV6: 31 | EA6: 1 | EB6: 2 | EC6: 3 | ED6: 4 | EE6: 5 | EF6: 6 | EG6: 7 | EH6: 8 | EI6: 9 | EJ6: 10 | EK6: 11 | EL6: 12 | EM6: 13 | EN6: 14 | EO6: 15 | EP6: 16 | EQ6: 17 | ER6: 18 | ES6: 19 | ET6: 20 | EU6: 21 | EV6: 22 | EW6: 23 | EX6: 24 | EY6: 25 | EZ6: 26 | FA6: 27 | FB6: 28 | FC6: 29 | FD6: 30 | FJ6: 1 | FK6: 2 | FL6: 3 | FM6: 4 | FN6: 5 | FO6: 6 | FP6: 7 | FQ6: 8 | FR6: 9 | FS6: 10 | FT6: 11 | FU6: 12 | FV6: 13 | FW6: 14 | FX6: 15 | FY6: 16 | FZ6: 17 | GA6: 18 | GB6: 19 | GC6: 20 | GD6: 21 | GE6: 22 | GF6: 23 | GG6: 24 | GH6: 25 | GI6: 26 | GJ6: 27 | GK6: 28 | GL6: 29 | GM6: 30 | GN6: 31
A7: =IF('กรอกข้อมูล นร1'!A5,'กรอกข้อมูล นร1'!A5,"") -> 1 | B7: ='กรอกข้อมูล นร1'!B5&"" | C7: ='กรอกข้อมูล นร1'!D5&"" | D7: =IF('กรอกข้อมูล นร1'!C5="","",'กรอกข้อมูล นร1'!C5) | E7: =IF(A7="","",$E$6) -> 100 | G7: / | H7: / | I7: / | J7: / | M7: / | N7: / | O7: / | P7: / | Q7: / | T7: / | U7: / | V7: =IF(COUNTIF($F7:$U7," /"),COUNTIF($F7:$U7," /"),"") -> 11 | W7: =IF(COUNTIF($F7:$U7,"ป"),COUNTIF($F7:$U7,"ป"),"") | X7: =IF(COUNTIF($F7:$U7,"ล"),COUNTIF($F7:$U7,"ล"),"") | Y7: =IF(COUNTIF($F7:$U7,"ข"),COUNTIF($F7:$U7,"ข"),"") | Z7: / | AA7: / | AE7: / | AF7: / | AG7: / | AH7: / | AI7: / | AL7: / | AM7: / | AN7: / | AO7: / | AP7: / | AS7: / | AT7: / | AU7: / | AV7: / | AW7: / | AZ7: / | BA7: / | BB7: / | BC7: / | BE7: =IF(COUNTIF($Z7:$BD7," /"),COUNTIF($Z7:$BD7," /"),"") -> 21 | BF7: =IF(COUNTIF($Z7:$BD7,"ป"),COUNTIF($Z7:$BD7,"ป"),"") | BG7: =IF(COUNTIF($Z7:$BD7,"ล"),COUNTIF($Z7:$BD7,"ล"),"") | BH7: =IF(COUNTIF($Z7:$BD7,"ข"),COUNTIF($Z7:$BD7,"ข"),"") | BI7: / | BL7: / | BM7: / | BN7: / | BO7: / | BP7: / | BS7: / | BT7: / | BZ7: / | CA7: / | CB7: / | CC7: / | CD7: / | CG7: / | CH7: / | CI7: / | CN7: =IF(COUNTIF($BI7:$CM7," /"),COUNTIF($BI7:$CM7," /"),"") -> 16 | CO7: =IF(COUNTIF($BI7:$CM7,"ป"),COUNTIF($BI7:$CM7,"ป"),"") | CP7: =IF(COUNTIF($BI7:$CM7,"ล"),COUNTIF($BI7:$CM7,"ล"),"") | CQ7: =IF(COUNTIF($BI7:$CM7,"ข"),COUNTIF($BI7:$CM7,"ข"),"") | CR7: / | CS7: / | CT7: / | CU7: / | CV7: / | CY7: / | CZ7: / | DA7: / | DB7: / | DF7: / | DG7: / | DH7: / | DI7: / | DJ7: / | DM7: / | DN7: / | DO7: / | DP7: / | DQ7: / | DT7: / | DU7: / | DV7: / | DW7: =IF(COUNTIF($CR7:$DV7," /"),COUNTIF($CR7:$DV7," /"),"") -> 22 | DX7: =IF(COUNTIF($CR7:$DV7,"ป"),COUNTIF($CR7:$DV7,"ป"),"") | DY7: =IF(COUNTIF($CR7:$DV7,"ล"),COUNTIF($CR7:$DV7,"ล"),"") | DZ7: =IF(COUNTIF($CR7:$DV7,"ข"),COUNTIF($CR7:$DV7,"ข"),"") | EA7: / | EB7: / | EE7: / | EF7: / | EG7: / | EH7: / | EI7: / | EL7: / | EM7: / | EN7: / | EO7: / | EP7: / | ES7: / | ET7: / | EU7: / | EV7: / | EW7: / | EZ7: / | FA7: / | FB7: / | FC7: / | FD7: / | FF7: =IF(COUNTIF($EA7:$FE7," /"),COUNTIF($EA7:$FE7," /"),"") -> 22 | FG7: =IF(COUNTIF($EA7:$FE7,"ป"),COUNTIF($EA7:$FE7,"ป"),"") | FH7: =IF(COUNTIF($EA7:$FE7,"ล"),COUNTIF($EA7:$FE7,"ล"),"") | FI7: =IF(COUNTIF($EA7:$FE7,"ข"),COUNTIF($EA7:$FE7,"ข"),"") | FL7: / | FM7: / | FN7: / | FO7: / | FP7: / | FS7: / | FT7: / | FU7: / | GO7: =IF(COUNTIF($FJ7:$GN7," /"),COUNTIF($FJ7:$GN7," /"),"") -> 8 | GP7: =IF(COUNTIF($FJ7:$GN7,"ป"),COUNTIF($FJ7:$GN7,"ป"),"") | GQ7: =IF(COUNTIF($FJ7:$GN7,"ล"),COUNTIF($FJ7:$GN7,"ล"),"") | GR7: =IF(COUNTIF($FJ7:$GN7,"ข"),COUNTIF($FJ7:$GN7,"ข"),"") | GS7: =IF(A7="","",SUM(V7,BE7,CN7,DW7,FF7,GO7)) -> 100 | GT7: =IF(A7="","",SUM(W7,BF7,CO7,DX7,FG7,GP7)) -> 0 | GU7: =IF(A7="","",SUM(X7,BG7,CP7,DY7,FH7,GQ7)) -> 0 | GV7: =IF(A7="","",SUM(Y7,ZX7,BH7,CQ7,DZ7,FI7,GR7)) -> 0 | GW7: =IF(A7="","",SUM(GS7,GT7,GU7,GV7)) -> 100
A8: =IF('กรอกข้อมูล นร1'!A6,'กรอกข้อมูล นร1'!A6,"") | B8: ='กรอกข้อมูล นร1'!B6&"" | C8: ='กรอกข้อมูล นร1'!D6&"" | D8: =IF('กรอกข้อมูล นร1'!C6="","",'กรอกข้อมูล นร1'!C6) | E8: =IF(A8="","",$E$6) | V8: =IF(COUNTIF($F8:$U8," /"),COUNTIF($F8:$U8," /"),"") | W8: =IF(COUNTIF($F8:$U8,"ป"),COUNTIF($F8:$U8,"ป"),"") | X8: =IF(COUNTIF($F8:$U8,"ล"),COUNTIF($F8:$U8,"ล"),"") | Y8: =IF(COUNTIF($F8:$U8,"ข"),COUNTIF($F8:$U8,"ข"),"") | BE8: =IF(COUNTIF($Z8:$BD8," /"),COUNTIF($Z8:$BD8," /"),"") | BF8: =IF(COUNTIF($Z8:$BD8,"ป"),COUNTIF($Z8:$BD8,"ป"),"") | BG8: =IF(COUNTIF($Z8:$BD8,"ล"),COUNTIF($Z8:$BD8,"ล"),"") | BH8: =IF(COUNTIF($Z8:$BD8,"ข"),COUNTIF($Z8:$BD8,"ข"),"") | CN8: =IF(COUNTIF($BI8:$CM8," /"),COUNTIF($BI8:$CM8," /"),"") | CO8: =IF(COUNTIF($BI8:$CM8,"ป"),COUNTIF($BI8:$CM8,"ป"),"") | CP8: =IF(COUNTIF($BI8:$CM8,"ล"),COUNTIF($BI8:$CM8,"ล"),"") | CQ8: =IF(COUNTIF($BI8:$CM8,"ข"),COUNTIF($BI8:$CM8,"ข"),"") | DW8: =IF(COUNTIF($CR8:$DV8," /"),COUNTIF($CR8:$DV8," /"),"") | DX8: =IF(COUNTIF($CR8:$DV8,"ป"),COUNTIF($CR8:$DV8,"ป"),"") | DY8: =IF(COUNTIF($CR8:$DV8,"ล"),COUNTIF($CR8:$DV8,"ล"),"") | DZ8: =IF(COUNTIF($CR8:$DV8,"ข"),COUNTIF($CR8:$DV8,"ข"),"") | FF8: =IF(COUNTIF($EA8:$FE8," /"),COUNTIF($EA8:$FE8," /"),"") | FG8: =IF(COUNTIF($EA8:$FE8,"ป"),COUNTIF($EA8:$FE8,"ป"),"") | FH8: =IF(COUNTIF($EA8:$FE8,"ล"),COUNTIF($EA8:$FE8,"ล"),"") | FI8: =IF(COUNTIF($EA8:$FE8,"ข"),COUNTIF($EA8:$FE8,"ข"),"") | GO8: =IF(COUNTIF($FJ8:$GN8," /"),COUNTIF($FJ8:$GN8," /"),"") | GP8: =IF(COUNTIF($FJ8:$GN8,"ป"),COUNTIF($FJ8:$GN8,"ป"),"") | GQ8: =IF(COUNTIF($FJ8:$GN8,"ล"),COUNTIF($FJ8:$GN8,"ล"),"") | GR8: =IF(COUNTIF($FJ8:$GN8,"ข"),COUNTIF($FJ8:$GN8,"ข"),"") | GS8: =IF(A8="","",SUM(V8,BE8,CN8,DW8,FF8,GO8)) | GT8: =IF(A8="","",SUM(W8,BF8,CO8,DX8,FG8,GP8)) | GU8: =IF(A8="","",SUM(X8,BG8,CP8,DY8,FH8,GQ8)) | GV8: =IF(A8="","",SUM(Y8,ZX8,BH8,CQ8,DZ8,FI8,GR8)) | GW8: =IF(A8="","",SUM(GS8,GT8,GU8,GV8))
A9: =IF('กรอกข้อมูล นร1'!A7,'กรอกข้อมูล นร1'!A7,"") | B9: ='กรอกข้อมูล นร1'!B7&"" | C9: ='กรอกข้อมูล นร1'!D7&"" | D9: =IF('กรอกข้อมูล นร1'!C7="","",'กรอกข้อมูล นร1'!C7) | E9: =IF(A9="","",$E$6) | V9: =IF(COUNTIF($F9:$U9," /"),COUNTIF($F9:$U9," /"),"") | W9: =IF(COUNTIF($F9:$U9,"ป"),COUNTIF($F9:$U9,"ป"),"") | X9: =IF(COUNTIF($F9:$U9,"ล"),COUNTIF($F9:$U9,"ล"),"") | Y9: =IF(COUNTIF($F9:$U9,"ข"),COUNTIF($F9:$U9,"ข"),"") | BE9: =IF(COUNTIF($Z9:$BD9," /"),COUNTIF($Z9:$BD9," /"),"") | BF9: =IF(COUNTIF($Z9:$BD9,"ป"),COUNTIF($Z9:$BD9,"ป"),"") | BG9: =IF(COUNTIF($Z9:$BD9,"ล"),COUNTIF($Z9:$BD9,"ล"),"") | BH9: =IF(COUNTIF($Z9:$BD9,"ข"),COUNTIF($Z9:$BD9,"ข"),"") | CN9: =IF(COUNTIF($BI9:$CM9," /"),COUNTIF($BI9:$CM9," /"),"") | CO9: =IF(COUNTIF($BI9:$CM9,"ป"),COUNTIF($BI9:$CM9,"ป"),"") | CP9: =IF(COUNTIF($BI9:$CM9,"ล"),COUNTIF($BI9:$CM9,"ล"),"") | CQ9: =IF(COUNTIF($BI9:$CM9,"ข"),COUNTIF($BI9:$CM9,"ข"),"") | DW9: =IF(COUNTIF($CR9:$DV9," /"),COUNTIF($CR9:$DV9," /"),"") | DX9: =IF(COUNTIF($CR9:$DV9,"ป"),COUNTIF($CR9:$DV9,"ป"),"") | DY9: =IF(COUNTIF($CR9:$DV9,"ล"),COUNTIF($CR9:$DV9,"ล"),"") | DZ9: =IF(COUNTIF($CR9:$DV9,"ข"),COUNTIF($CR9:$DV9,"ข"),"") | FF9: =IF(COUNTIF($EA9:$FE9," /"),COUNTIF($EA9:$FE9," /"),"") | FG9: =IF(COUNTIF($EA9:$FE9,"ป"),COUNTIF($EA9:$FE9,"ป"),"") | FH9: =IF(COUNTIF($EA9:$FE9,"ล"),COUNTIF($EA9:$FE9,"ล"),"") | FI9: =IF(COUNTIF($EA9:$FE9,"ข"),COUNTIF($EA9:$FE9,"ข"),"") | GO9: =IF(COUNTIF($FJ9:$GN9," /"),COUNTIF($FJ9:$GN9," /"),"") | GP9: =IF(COUNTIF($FJ9:$GN9,"ป"),COUNTIF($FJ9:$GN9,"ป"),"") | GQ9: =IF(COUNTIF($FJ9:$GN9,"ล"),COUNTIF($FJ9:$GN9,"ล"),"") | GR9: =IF(COUNTIF($FJ9:$GN9,"ข"),COUNTIF($FJ9:$GN9,"ข"),"") | GS9: =IF(A9="","",SUM(V9,BE9,CN9,DW9,FF9,GO9)) | GT9: =IF(A9="","",SUM(W9,BF9,CO9,DX9,FG9,GP9)) | GU9: =IF(A9="","",SUM(X9,BG9,CP9,DY9,FH9,GQ9)) | GV9: =IF(A9="","",SUM(Y9,ZX9,BH9,CQ9,DZ9,FI9,GR9)) | GW9: =IF(A9="","",SUM(GS9,GT9,GU9,GV9))
A10: =IF('กรอกข้อมูล นร1'!A8,'กรอกข้อมูล นร1'!A8,"") | B10: ='กรอกข้อมูล นร1'!B8&"" | C10: ='กรอกข้อมูล นร1'!D8&"" | D10: =IF('กรอกข้อมูล นร1'!C8="","",'กรอกข้อมูล นร1'!C8) | E10: =IF(A10="","",$E$6) | V10: =IF(COUNTIF($F10:$U10," /"),COUNTIF($F10:$U10," /"),"") | W10: =IF(COUNTIF($F10:$U10,"ป"),COUNTIF($F10:$U10,"ป"),"") | X10: =IF(COUNTIF($F10:$U10,"ล"),COUNTIF($F10:$U10,"ล"),"") | Y10: =IF(COUNTIF($F10:$U10,"ข"),COUNTIF($F10:$U10,"ข"),"") | BE10: =IF(COUNTIF($Z10:$BD10," /"),COUNTIF($Z10:$BD10," /"),"") | BF10: =IF(COUNTIF($Z10:$BD10,"ป"),COUNTIF($Z10:$BD10,"ป"),"") | BG10: =IF(COUNTIF($Z10:$BD10,"ล"),COUNTIF($Z10:$BD10,"ล"),"") | BH10: =IF(COUNTIF($Z10:$BD10,"ข"),COUNTIF($Z10:$BD10,"ข"),"") | CN10: =IF(COUNTIF($BI10:$CM10," /"),COUNTIF($BI10:$CM10," /"),"") | CO10: =IF(COUNTIF($BI10:$CM10,"ป"),COUNTIF($BI10:$CM10,"ป"),"") | CP10: =IF(COUNTIF($BI10:$CM10,"ล"),COUNTIF($BI10:$CM10,"ล"),"") | CQ10: =IF(COUNTIF($BI10:$CM10,"ข"),COUNTIF($BI10:$CM10,"ข"),"") | DW10: =IF(COUNTIF($CR10:$DV10," /"),COUNTIF($CR10:$DV10," /"),"") | DX10: =IF(COUNTIF($CR10:$DV10,"ป"),COUNTIF($CR10:$DV10,"ป"),"") | DY10: =IF(COUNTIF($CR10:$DV10,"ล"),COUNTIF($CR10:$DV10,"ล"),"") | DZ10: =IF(COUNTIF($CR10:$DV10,"ข"),COUNTIF($CR10:$DV10,"ข"),"") | FF10: =IF(COUNTIF($EA10:$FE10," /"),COUNTIF($EA10:$FE10," /"),"") | FG10: =IF(COUNTIF($EA10:$FE10,"ป"),COUNTIF($EA10:$FE10,"ป"),"") | FH10: =IF(COUNTIF($EA10:$FE10,"ล"),COUNTIF($EA10:$FE10,"ล"),"") | FI10: =IF(COUNTIF($EA10:$FE10,"ข"),COUNTIF($EA10:$FE10,"ข"),"") | GO10: =IF(COUNTIF($FJ10:$GN10," /"),COUNTIF($FJ10:$GN10," /"),"") | GP10: =IF(COUNTIF($FJ10:$GN10,"ป"),COUNTIF($FJ10:$GN10,"ป"),"") | GQ10: =IF(COUNTIF($FJ10:$GN10,"ล"),COUNTIF($FJ10:$GN10,"ล"),"") | GR10: =IF(COUNTIF($FJ10:$GN10,"ข"),COUNTIF($FJ10:$GN10,"ข"),"") | GS10: =IF(A10="","",SUM(V10,BE10,CN10,DW10,FF10,GO10)) | GT10: =IF(A10="","",SUM(W10,BF10,CO10,DX10,FG10,GP10)) | GU10: =IF(A10="","",SUM(X10,BG10,CP10,DY10,FH10,GQ10)) | GV10: =IF(A10="","",SUM(Y10,ZX10,BH10,CQ10,DZ10,FI10,GR10)) | GW10: =IF(A10="","",SUM(GS10,GT10,GU10,GV10))
A11: =IF('กรอกข้อมูล นร1'!A9,'กรอกข้อมูล นร1'!A9,"") | B11: ='กรอกข้อมูล นร1'!B9&"" | C11: ='กรอกข้อมูล นร1'!D9&"" | D11: =IF('กรอกข้อมูล นร1'!C9="","",'กรอกข้อมูล นร1'!C9) | E11: =IF(A11="","",$E$6) | V11: =IF(COUNTIF($F11:$U11," /"),COUNTIF($F11:$U11," /"),"") | W11: =IF(COUNTIF($F11:$U11,"ป"),COUNTIF($F11:$U11,"ป"),"") | X11: =IF(COUNTIF($F11:$U11,"ล"),COUNTIF($F11:$U11,"ล"),"") | Y11: =IF(COUNTIF($F11:$U11,"ข"),COUNTIF($F11:$U11,"ข"),"") | BE11: =IF(COUNTIF($Z11:$BD11," /"),COUNTIF($Z11:$BD11," /"),"") | BF11: =IF(COUNTIF($Z11:$BD11,"ป"),COUNTIF($Z11:$BD11,"ป"),"") | BG11: =IF(COUNTIF($Z11:$BD11,"ล"),COUNTIF($Z11:$BD11,"ล"),"") | BH11: =IF(COUNTIF($Z11:$BD11,"ข"),COUNTIF($Z11:$BD11,"ข"),"") | CN11: =IF(COUNTIF($BI11:$CM11," /"),COUNTIF($BI11:$CM11," /"),"") | CO11: =IF(COUNTIF($BI11:$CM11,"ป"),COUNTIF($BI11:$CM11,"ป"),"") | CP11: =IF(COUNTIF($BI11:$CM11,"ล"),COUNTIF($BI11:$CM11,"ล"),"") | CQ11: =IF(COUNTIF($BI11:$CM11,"ข"),COUNTIF($BI11:$CM11,"ข"),"") | DW11: =IF(COUNTIF($CR11:$DV11," /"),COUNTIF($CR11:$DV11," /"),"") | DX11: =IF(COUNTIF($CR11:$DV11,"ป"),COUNTIF($CR11:$DV11,"ป"),"") | DY11: =IF(COUNTIF($CR11:$DV11,"ล"),COUNTIF($CR11:$DV11,"ล"),"") | DZ11: =IF(COUNTIF($CR11:$DV11,"ข"),COUNTIF($CR11:$DV11,"ข"),"") | FF11: =IF(COUNTIF($EA11:$FE11," /"),COUNTIF($EA11:$FE11," /"),"") | FG11: =IF(COUNTIF($EA11:$FE11,"ป"),COUNTIF($EA11:$FE11,"ป"),"") | FH11: =IF(COUNTIF($EA11:$FE11,"ล"),COUNTIF($EA11:$FE11,"ล"),"") | FI11: =IF(COUNTIF($EA11:$FE11,"ข"),COUNTIF($EA11:$FE11,"ข"),"") | GO11: =IF(COUNTIF($FJ11:$GN11," /"),COUNTIF($FJ11:$GN11," /"),"") | GP11: =IF(COUNTIF($FJ11:$GN11,"ป"),COUNTIF($FJ11:$GN11,"ป"),"") | GQ11: =IF(COUNTIF($FJ11:$GN11,"ล"),COUNTIF($FJ11:$GN11,"ล"),"") | GR11: =IF(COUNTIF($FJ11:$GN11,"ข"),COUNTIF($FJ11:$GN11,"ข"),"") | GS11: =IF(A11="","",SUM(V11,BE11,CN11,DW11,FF11,GO11)) | GT11: =IF(A11="","",SUM(W11,BF11,CO11,DX11,FG11,GP11)) | GU11: =IF(A11="","",SUM(X11,BG11,CP11,DY11,FH11,GQ11)) | GV11: =IF(A11="","",SUM(Y11,ZX11,BH11,CQ11,DZ11,FI11,GR11)) | GW11: =IF(A11="","",SUM(GS11,GT11,GU11,GV11))
A12: =IF('กรอกข้อมูล นร1'!A10,'กรอกข้อมูล นร1'!A10,"") | B12: ='กรอกข้อมูล นร1'!B10&"" | C12: ='กรอกข้อมูล นร1'!D10&"" | D12: =IF('กรอกข้อมูล นร1'!C10="","",'กรอกข้อมูล นร1'!C10) | E12: =IF(A12="","",$E$6) | V12: =IF(COUNTIF($F12:$U12," /"),COUNTIF($F12:$U12," /"),"") | W12: =IF(COUNTIF($F12:$U12,"ป"),COUNTIF($F12:$U12,"ป"),"") | X12: =IF(COUNTIF($F12:$U12,"ล"),COUNTIF($F12:$U12,"ล"),"") | Y12: =IF(COUNTIF($F12:$U12,"ข"),COUNTIF($F12:$U12,"ข"),"") | BE12: =IF(COUNTIF($Z12:$BD12," /"),COUNTIF($Z12:$BD12," /"),"") | BF12: =IF(COUNTIF($Z12:$BD12,"ป"),COUNTIF($Z12:$BD12,"ป"),"") | BG12: =IF(COUNTIF($Z12:$BD12,"ล"),COUNTIF($Z12:$BD12,"ล"),"") | BH12: =IF(COUNTIF($Z12:$BD12,"ข"),COUNTIF($Z12:$BD12,"ข"),"") | CN12: =IF(COUNTIF($BI12:$CM12," /"),COUNTIF($BI12:$CM12," /"),"") | CO12: =IF(COUNTIF($BI12:$CM12,"ป"),COUNTIF($BI12:$CM12,"ป"),"") | CP12: =IF(COUNTIF($BI12:$CM12,"ล"),COUNTIF($BI12:$CM12,"ล"),"") | CQ12: =IF(COUNTIF($BI12:$CM12,"ข"),COUNTIF($BI12:$CM12,"ข"),"") | DW12: =IF(COUNTIF($CR12:$DV12," /"),COUNTIF($CR12:$DV12," /"),"") | DX12: =IF(COUNTIF($CR12:$DV12,"ป"),COUNTIF($CR12:$DV12,"ป"),"") | DY12: =IF(COUNTIF($CR12:$DV12,"ล"),COUNTIF($CR12:$DV12,"ล"),"") | DZ12: =IF(COUNTIF($CR12:$DV12,"ข"),COUNTIF($CR12:$DV12,"ข"),"") | FF12: =IF(COUNTIF($EA12:$FE12," /"),COUNTIF($EA12:$FE12," /"),"") | FG12: =IF(COUNTIF($EA12:$FE12,"ป"),COUNTIF($EA12:$FE12,"ป"),"") | FH12: =IF(COUNTIF($EA12:$FE12,"ล"),COUNTIF($EA12:$FE12,"ล"),"") | FI12: =IF(COUNTIF($EA12:$FE12,"ข"),COUNTIF($EA12:$FE12,"ข"),"") | GO12: =IF(COUNTIF($FJ12:$GN12," /"),COUNTIF($FJ12:$GN12," /"),"") | GP12: =IF(COUNTIF($FJ12:$GN12,"ป"),COUNTIF($FJ12:$GN12,"ป"),"") | GQ12: =IF(COUNTIF($FJ12:$GN12,"ล"),COUNTIF($FJ12:$GN12,"ล"),"") | GR12: =IF(COUNTIF($FJ12:$GN12,"ข"),COUNTIF($FJ12:$GN12,"ข"),"") | GS12: =IF(A12="","",SUM(V12,BE12,CN12,DW12,FF12,GO12)) | GT12: =IF(A12="","",SUM(W12,BF12,CO12,DX12,FG12,GP12)) | GU12: =IF(A12="","",SUM(X12,BG12,CP12,DY12,FH12,GQ12)) | GV12: =IF(A12="","",SUM(Y12,ZX12,BH12,CQ12,DZ12,FI12,GR12)) | GW12: =IF(A12="","",SUM(GS12,GT12,GU12,GV12))
A13: =IF('กรอกข้อมูล นร1'!A11,'กรอกข้อมูล นร1'!A11,"") | B13: ='กรอกข้อมูล นร1'!B11&"" | C13: ='กรอกข้อมูล นร1'!D11&"" | D13: =IF('กรอกข้อมูล นร1'!C11="","",'กรอกข้อมูล นร1'!C11) | E13: =IF(A13="","",$E$6) | V13: =IF(COUNTIF($F13:$U13," /"),COUNTIF($F13:$U13," /"),"") | W13: =IF(COUNTIF($F13:$U13,"ป"),COUNTIF($F13:$U13,"ป"),"") | X13: =IF(COUNTIF($F13:$U13,"ล"),COUNTIF($F13:$U13,"ล"),"") | Y13: =IF(COUNTIF($F13:$U13,"ข"),COUNTIF($F13:$U13,"ข"),"") | BE13: =IF(COUNTIF($Z13:$BD13," /"),COUNTIF($Z13:$BD13," /"),"") | BF13: =IF(COUNTIF($Z13:$BD13,"ป"),COUNTIF($Z13:$BD13,"ป"),"") | BG13: =IF(COUNTIF($Z13:$BD13,"ล"),COUNTIF($Z13:$BD13,"ล"),"") | BH13: =IF(COUNTIF($Z13:$BD13,"ข"),COUNTIF($Z13:$BD13,"ข"),"") | CN13: =IF(COUNTIF($BI13:$CM13," /"),COUNTIF($BI13:$CM13," /"),"") | CO13: =IF(COUNTIF($BI13:$CM13,"ป"),COUNTIF($BI13:$CM13,"ป"),"") | CP13: =IF(COUNTIF($BI13:$CM13,"ล"),COUNTIF($BI13:$CM13,"ล"),"") | CQ13: =IF(COUNTIF($BI13:$CM13,"ข"),COUNTIF($BI13:$CM13,"ข"),"") | DW13: =IF(COUNTIF($CR13:$DV13," /"),COUNTIF($CR13:$DV13," /"),"") | DX13: =IF(COUNTIF($CR13:$DV13,"ป"),COUNTIF($CR13:$DV13,"ป"),"") | DY13: =IF(COUNTIF($CR13:$DV13,"ล"),COUNTIF($CR13:$DV13,"ล"),"") | DZ13: =IF(COUNTIF($CR13:$DV13,"ข"),COUNTIF($CR13:$DV13,"ข"),"") | FF13: =IF(COUNTIF($EA13:$FE13," /"),COUNTIF($EA13:$FE13," /"),"") | FG13: =IF(COUNTIF($EA13:$FE13,"ป"),COUNTIF($EA13:$FE13,"ป"),"") | FH13: =IF(COUNTIF($EA13:$FE13,"ล"),COUNTIF($EA13:$FE13,"ล"),"") | FI13: =IF(COUNTIF($EA13:$FE13,"ข"),COUNTIF($EA13:$FE13,"ข"),"") | GO13: =IF(COUNTIF($FJ13:$GN13," /"),COUNTIF($FJ13:$GN13," /"),"") | GP13: =IF(COUNTIF($FJ13:$GN13,"ป"),COUNTIF($FJ13:$GN13,"ป"),"") | GQ13: =IF(COUNTIF($FJ13:$GN13,"ล"),COUNTIF($FJ13:$GN13,"ล"),"") | GR13: =IF(COUNTIF($FJ13:$GN13,"ข"),COUNTIF($FJ13:$GN13,"ข"),"") | GS13: =IF(A13="","",SUM(V13,BE13,CN13,DW13,FF13,GO13)) | GT13: =IF(A13="","",SUM(W13,BF13,CO13,DX13,FG13,GP13)) | GU13: =IF(A13="","",SUM(X13,BG13,CP13,DY13,FH13,GQ13)) | GV13: =IF(A13="","",SUM(Y13,ZX13,BH13,CQ13,DZ13,FI13,GR13)) | GW13: =IF(A13="","",SUM(GS13,GT13,GU13,GV13))
A14: =IF('กรอกข้อมูล นร1'!A12,'กรอกข้อมูล นร1'!A12,"") | B14: ='กรอกข้อมูล นร1'!B12&"" | C14: ='กรอกข้อมูล นร1'!D12&"" | D14: =IF('กรอกข้อมูล นร1'!C12="","",'กรอกข้อมูล นร1'!C12) | E14: =IF(A14="","",$E$6) | V14: =IF(COUNTIF($F14:$U14," /"),COUNTIF($F14:$U14," /"),"") | W14: =IF(COUNTIF($F14:$U14,"ป"),COUNTIF($F14:$U14,"ป"),"") | X14: =IF(COUNTIF($F14:$U14,"ล"),COUNTIF($F14:$U14,"ล"),"") | Y14: =IF(COUNTIF($F14:$U14,"ข"),COUNTIF($F14:$U14,"ข"),"") | BE14: =IF(COUNTIF($Z14:$BD14," /"),COUNTIF($Z14:$BD14," /"),"") | BF14: =IF(COUNTIF($Z14:$BD14,"ป"),COUNTIF($Z14:$BD14,"ป"),"") | BG14: =IF(COUNTIF($Z14:$BD14,"ล"),COUNTIF($Z14:$BD14,"ล"),"") | BH14: =IF(COUNTIF($Z14:$BD14,"ข"),COUNTIF($Z14:$BD14,"ข"),"") | CN14: =IF(COUNTIF($BI14:$CM14," /"),COUNTIF($BI14:$CM14," /"),"") | CO14: =IF(COUNTIF($BI14:$CM14,"ป"),COUNTIF($BI14:$CM14,"ป"),"") | CP14: =IF(COUNTIF($BI14:$CM14,"ล"),COUNTIF($BI14:$CM14,"ล"),"") | CQ14: =IF(COUNTIF($BI14:$CM14,"ข"),COUNTIF($BI14:$CM14,"ข"),"") | DW14: =IF(COUNTIF($CR14:$DV14," /"),COUNTIF($CR14:$DV14," /"),"") | DX14: =IF(COUNTIF($CR14:$DV14,"ป"),COUNTIF($CR14:$DV14,"ป"),"") | DY14: =IF(COUNTIF($CR14:$DV14,"ล"),COUNTIF($CR14:$DV14,"ล"),"") | DZ14: =IF(COUNTIF($CR14:$DV14,"ข"),COUNTIF($CR14:$DV14,"ข"),"") | FF14: =IF(COUNTIF($EA14:$FE14," /"),COUNTIF($EA14:$FE14," /"),"") | FG14: =IF(COUNTIF($EA14:$FE14,"ป"),COUNTIF($EA14:$FE14,"ป"),"") | FH14: =IF(COUNTIF($EA14:$FE14,"ล"),COUNTIF($EA14:$FE14,"ล"),"") | FI14: =IF(COUNTIF($EA14:$FE14,"ข"),COUNTIF($EA14:$FE14,"ข"),"") | GO14: =IF(COUNTIF($FJ14:$GN14," /"),COUNTIF($FJ14:$GN14," /"),"") | GP14: =IF(COUNTIF($FJ14:$GN14,"ป"),COUNTIF($FJ14:$GN14,"ป"),"") | GQ14: =IF(COUNTIF($FJ14:$GN14,"ล"),COUNTIF($FJ14:$GN14,"ล"),"") | GR14: =IF(COUNTIF($FJ14:$GN14,"ข"),COUNTIF($FJ14:$GN14,"ข"),"") | GS14: =IF(A14="","",SUM(V14,BE14,CN14,DW14,FF14,GO14)) | GT14: =IF(A14="","",SUM(W14,BF14,CO14,DX14,FG14,GP14)) | GU14: =IF(A14="","",SUM(X14,BG14,CP14,DY14,FH14,GQ14)) | GV14: =IF(A14="","",SUM(Y14,ZX14,BH14,CQ14,DZ14,FI14,GR14)) | GW14: =IF(A14="","",SUM(GS14,GT14,GU14,GV14))
A15: =IF('กรอกข้อมูล นร1'!A13,'กรอกข้อมูล นร1'!A13,"") | B15: ='กรอกข้อมูล นร1'!B13&"" | C15: ='กรอกข้อมูล นร1'!D13&"" | D15: =IF('กรอกข้อมูล นร1'!C13="","",'กรอกข้อมูล นร1'!C13) | E15: =IF(A15="","",$E$6) | V15: =IF(COUNTIF($F15:$U15," /"),COUNTIF($F15:$U15," /"),"") | W15: =IF(COUNTIF($F15:$U15,"ป"),COUNTIF($F15:$U15,"ป"),"") | X15: =IF(COUNTIF($F15:$U15,"ล"),COUNTIF($F15:$U15,"ล"),"") | Y15: =IF(COUNTIF($F15:$U15,"ข"),COUNTIF($F15:$U15,"ข"),"") | BE15: =IF(COUNTIF($Z15:$BD15," /"),COUNTIF($Z15:$BD15," /"),"") | BF15: =IF(COUNTIF($Z15:$BD15,"ป"),COUNTIF($Z15:$BD15,"ป"),"") | BG15: =IF(COUNTIF($Z15:$BD15,"ล"),COUNTIF($Z15:$BD15,"ล"),"") | BH15: =IF(COUNTIF($Z15:$BD15,"ข"),COUNTIF($Z15:$BD15,"ข"),"") | CN15: =IF(COUNTIF($BI15:$CM15," /"),COUNTIF($BI15:$CM15," /"),"") | CO15: =IF(COUNTIF($BI15:$CM15,"ป"),COUNTIF($BI15:$CM15,"ป"),"") | CP15: =IF(COUNTIF($BI15:$CM15,"ล"),COUNTIF($BI15:$CM15,"ล"),"") | CQ15: =IF(COUNTIF($BI15:$CM15,"ข"),COUNTIF($BI15:$CM15,"ข"),"") | DW15: =IF(COUNTIF($CR15:$DV15," /"),COUNTIF($CR15:$DV15," /"),"") | DX15: =IF(COUNTIF($CR15:$DV15,"ป"),COUNTIF($CR15:$DV15,"ป"),"") | DY15: =IF(COUNTIF($CR15:$DV15,"ล"),COUNTIF($CR15:$DV15,"ล"),"") | DZ15: =IF(COUNTIF($CR15:$DV15,"ข"),COUNTIF($CR15:$DV15,"ข"),"") | FF15: =IF(COUNTIF($EA15:$FE15," /"),COUNTIF($EA15:$FE15," /"),"") | FG15: =IF(COUNTIF($EA15:$FE15,"ป"),COUNTIF($EA15:$FE15,"ป"),"") | FH15: =IF(COUNTIF($EA15:$FE15,"ล"),COUNTIF($EA15:$FE15,"ล"),"") | FI15: =IF(COUNTIF($EA15:$FE15,"ข"),COUNTIF($EA15:$FE15,"ข"),"") | GO15: =IF(COUNTIF($FJ15:$GN15," /"),COUNTIF($FJ15:$GN15," /"),"") | GP15: =IF(COUNTIF($FJ15:$GN15,"ป"),COUNTIF($FJ15:$GN15,"ป"),"") | GQ15: =IF(COUNTIF($FJ15:$GN15,"ล"),COUNTIF($FJ15:$GN15,"ล"),"") | GR15: =IF(COUNTIF($FJ15:$GN15,"ข"),COUNTIF($FJ15:$GN15,"ข"),"") | GS15: =IF(A15="","",SUM(V15,BE15,CN15,DW15,FF15,GO15)) | GT15: =IF(A15="","",SUM(W15,BF15,CO15,DX15,FG15,GP15)) | GU15: =IF(A15="","",SUM(X15,BG15,CP15,DY15,FH15,GQ15)) | GV15: =IF(A15="","",SUM(Y15,ZX15,BH15,CQ15,DZ15,FI15,GR15)) | GW15: =IF(A15="","",SUM(GS15,GT15,GU15,GV15))
A16: =IF('กรอกข้อมูล นร1'!A14,'กรอกข้อมูล นร1'!A14,"") | B16: ='กรอกข้อมูล นร1'!B14&"" | C16: ='กรอกข้อมูล นร1'!D14&"" | D16: =IF('กรอกข้อมูล นร1'!C14="","",'กรอกข้อมูล นร1'!C14) | E16: =IF(A16="","",$E$6) | V16: =IF(COUNTIF($F16:$U16," /"),COUNTIF($F16:$U16," /"),"") | W16: =IF(COUNTIF($F16:$U16,"ป"),COUNTIF($F16:$U16,"ป"),"") | X16: =IF(COUNTIF($F16:$U16,"ล"),COUNTIF($F16:$U16,"ล"),"") | Y16: =IF(COUNTIF($F16:$U16,"ข"),COUNTIF($F16:$U16,"ข"),"") | BE16: =IF(COUNTIF($Z16:$BD16," /"),COUNTIF($Z16:$BD16," /"),"") | BF16: =IF(COUNTIF($Z16:$BD16,"ป"),COUNTIF($Z16:$BD16,"ป"),"") | BG16: =IF(COUNTIF($Z16:$BD16,"ล"),COUNTIF($Z16:$BD16,"ล"),"") | BH16: =IF(COUNTIF($Z16:$BD16,"ข"),COUNTIF($Z16:$BD16,"ข"),"") | CN16: =IF(COUNTIF($BI16:$CM16," /"),COUNTIF($BI16:$CM16," /"),"") | CO16: =IF(COUNTIF($BI16:$CM16,"ป"),COUNTIF($BI16:$CM16,"ป"),"") | CP16: =IF(COUNTIF($BI16:$CM16,"ล"),COUNTIF($BI16:$CM16,"ล"),"") | CQ16: =IF(COUNTIF($BI16:$CM16,"ข"),COUNTIF($BI16:$CM16,"ข"),"") | DW16: =IF(COUNTIF($CR16:$DV16," /"),COUNTIF($CR16:$DV16," /"),"") | DX16: =IF(COUNTIF($CR16:$DV16,"ป"),COUNTIF($CR16:$DV16,"ป"),"") | DY16: =IF(COUNTIF($CR16:$DV16,"ล"),COUNTIF($CR16:$DV16,"ล"),"") | DZ16: =IF(COUNTIF($CR16:$DV16,"ข"),COUNTIF($CR16:$DV16,"ข"),"") | FF16: =IF(COUNTIF($EA16:$FE16," /"),COUNTIF($EA16:$FE16," /"),"") | FG16: =IF(COUNTIF($EA16:$FE16,"ป"),COUNTIF($EA16:$FE16,"ป"),"") | FH16: =IF(COUNTIF($EA16:$FE16,"ล"),COUNTIF($EA16:$FE16,"ล"),"") | FI16: =IF(COUNTIF($EA16:$FE16,"ข"),COUNTIF($EA16:$FE16,"ข"),"") | GO16: =IF(COUNTIF($FJ16:$GN16," /"),COUNTIF($FJ16:$GN16," /"),"") | GP16: =IF(COUNTIF($FJ16:$GN16,"ป"),COUNTIF($FJ16:$GN16,"ป"),"") | GQ16: =IF(COUNTIF($FJ16:$GN16,"ล"),COUNTIF($FJ16:$GN16,"ล"),"") | GR16: =IF(COUNTIF($FJ16:$GN16,"ข"),COUNTIF($FJ16:$GN16,"ข"),"") | GS16: =IF(A16="","",SUM(V16,BE16,CN16,DW16,FF16,GO16)) | GT16: =IF(A16="","",SUM(W16,BF16,CO16,DX16,FG16,GP16)) | GU16: =IF(A16="","",SUM(X16,BG16,CP16,DY16,FH16,GQ16)) | GV16: =IF(A16="","",SUM(Y16,ZX16,BH16,CQ16,DZ16,FI16,GR16)) | GW16: =IF(A16="","",SUM(GS16,GT16,GU16,GV16))
A17: =IF('กรอกข้อมูล นร1'!A15,'กรอกข้อมูล นร1'!A15,"") | B17: ='กรอกข้อมูล นร1'!B15&"" | C17: ='กรอกข้อมูล นร1'!D15&"" | D17: =IF('กรอกข้อมูล นร1'!C15="","",'กรอกข้อมูล นร1'!C15) | E17: =IF(A17="","",$E$6) | V17: =IF(COUNTIF($F17:$U17," /"),COUNTIF($F17:$U17," /"),"") | W17: =IF(COUNTIF($F17:$U17,"ป"),COUNTIF($F17:$U17,"ป"),"") | X17: =IF(COUNTIF($F17:$U17,"ล"),COUNTIF($F17:$U17,"ล"),"") | Y17: =IF(COUNTIF($F17:$U17,"ข"),COUNTIF($F17:$U17,"ข"),"") | BE17: =IF(COUNTIF($Z17:$BD17," /"),COUNTIF($Z17:$BD17," /"),"") | BF17: =IF(COUNTIF($Z17:$BD17,"ป"),COUNTIF($Z17:$BD17,"ป"),"") | BG17: =IF(COUNTIF($Z17:$BD17,"ล"),COUNTIF($Z17:$BD17,"ล"),"") | BH17: =IF(COUNTIF($Z17:$BD17,"ข"),COUNTIF($Z17:$BD17,"ข"),"") | CN17: =IF(COUNTIF($BI17:$CM17," /"),COUNTIF($BI17:$CM17," /"),"") | CO17: =IF(COUNTIF($BI17:$CM17,"ป"),COUNTIF($BI17:$CM17,"ป"),"") | CP17: =IF(COUNTIF($BI17:$CM17,"ล"),COUNTIF($BI17:$CM17,"ล"),"") | CQ17: =IF(COUNTIF($BI17:$CM17,"ข"),COUNTIF($BI17:$CM17,"ข"),"") | DW17: =IF(COUNTIF($CR17:$DV17," /"),COUNTIF($CR17:$DV17," /"),"") | DX17: =IF(COUNTIF($CR17:$DV17,"ป"),COUNTIF($CR17:$DV17,"ป"),"") | DY17: =IF(COUNTIF($CR17:$DV17,"ล"),COUNTIF($CR17:$DV17,"ล"),"") | DZ17: =IF(COUNTIF($CR17:$DV17,"ข"),COUNTIF($CR17:$DV17,"ข"),"") | FF17: =IF(COUNTIF($EA17:$FE17," /"),COUNTIF($EA17:$FE17," /"),"") | FG17: =IF(COUNTIF($EA17:$FE17,"ป"),COUNTIF($EA17:$FE17,"ป"),"") | FH17: =IF(COUNTIF($EA17:$FE17,"ล"),COUNTIF($EA17:$FE17,"ล"),"") | FI17: =IF(COUNTIF($EA17:$FE17,"ข"),COUNTIF($EA17:$FE17,"ข"),"") | GO17: =IF(COUNTIF($FJ17:$GN17," /"),COUNTIF($FJ17:$GN17," /"),"") | GP17: =IF(COUNTIF($FJ17:$GN17,"ป"),COUNTIF($FJ17:$GN17,"ป"),"") | GQ17: =IF(COUNTIF($FJ17:$GN17,"ล"),COUNTIF($FJ17:$GN17,"ล"),"") | GR17: =IF(COUNTIF($FJ17:$GN17,"ข"),COUNTIF($FJ17:$GN17,"ข"),"") | GS17: =IF(A17="","",SUM(V17,BE17,CN17,DW17,FF17,GO17)) | GT17: =IF(A17="","",SUM(W17,BF17,CO17,DX17,FG17,GP17)) | GU17: =IF(A17="","",SUM(X17,BG17,CP17,DY17,FH17,GQ17)) | GV17: =IF(A17="","",SUM(Y17,ZX17,BH17,CQ17,DZ17,FI17,GR17)) | GW17: =IF(A17="","",SUM(GS17,GT17,GU17,GV17))
A18: =IF('กรอกข้อมูล นร1'!A16,'กรอกข้อมูล นร1'!A16,"") | B18: ='กรอกข้อมูล นร1'!B16&"" | C18: ='กรอกข้อมูล นร1'!D16&"" | D18: =IF('กรอกข้อมูล นร1'!C16="","",'กรอกข้อมูล นร1'!C16) | E18: =IF(A18="","",$E$6) | V18: =IF(COUNTIF($F18:$U18," /"),COUNTIF($F18:$U18," /"),"") | W18: =IF(COUNTIF($F18:$U18,"ป"),COUNTIF($F18:$U18,"ป"),"") | X18: =IF(COUNTIF($F18:$U18,"ล"),COUNTIF($F18:$U18,"ล"),"") | Y18: =IF(COUNTIF($F18:$U18,"ข"),COUNTIF($F18:$U18,"ข"),"") | BE18: =IF(COUNTIF($Z18:$BD18," /"),COUNTIF($Z18:$BD18," /"),"") | BF18: =IF(COUNTIF($Z18:$BD18,"ป"),COUNTIF($Z18:$BD18,"ป"),"") | BG18: =IF(COUNTIF($Z18:$BD18,"ล"),COUNTIF($Z18:$BD18,"ล"),"") | BH18: =IF(COUNTIF($Z18:$BD18,"ข"),COUNTIF($Z18:$BD18,"ข"),"") | CN18: =IF(COUNTIF($BI18:$CM18," /"),COUNTIF($BI18:$CM18," /"),"") | CO18: =IF(COUNTIF($BI18:$CM18,"ป"),COUNTIF($BI18:$CM18,"ป"),"") | CP18: =IF(COUNTIF($BI18:$CM18,"ล"),COUNTIF($BI18:$CM18,"ล"),"") | CQ18: =IF(COUNTIF($BI18:$CM18,"ข"),COUNTIF($BI18:$CM18,"ข"),"") | DW18: =IF(COUNTIF($CR18:$DV18," /"),COUNTIF($CR18:$DV18," /"),"") | DX18: =IF(COUNTIF($CR18:$DV18,"ป"),COUNTIF($CR18:$DV18,"ป"),"") | DY18: =IF(COUNTIF($CR18:$DV18,"ล"),COUNTIF($CR18:$DV18,"ล"),"") | DZ18: =IF(COUNTIF($CR18:$DV18,"ข"),COUNTIF($CR18:$DV18,"ข"),"") | FF18: =IF(COUNTIF($EA18:$FE18," /"),COUNTIF($EA18:$FE18," /"),"") | FG18: =IF(COUNTIF($EA18:$FE18,"ป"),COUNTIF($EA18:$FE18,"ป"),"") | FH18: =IF(COUNTIF($EA18:$FE18,"ล"),COUNTIF($EA18:$FE18,"ล"),"") | FI18: =IF(COUNTIF($EA18:$FE18,"ข"),COUNTIF($EA18:$FE18,"ข"),"") | GO18: =IF(COUNTIF($FJ18:$GN18," /"),COUNTIF($FJ18:$GN18," /"),"") | GP18: =IF(COUNTIF($FJ18:$GN18,"ป"),COUNTIF($FJ18:$GN18,"ป"),"") | GQ18: =IF(COUNTIF($FJ18:$GN18,"ล"),COUNTIF($FJ18:$GN18,"ล"),"") | GR18: =IF(COUNTIF($FJ18:$GN18,"ข"),COUNTIF($FJ18:$GN18,"ข"),"") | GS18: =IF(A18="","",SUM(V18,BE18,CN18,DW18,FF18,GO18)) | GT18: =IF(A18="","",SUM(W18,BF18,CO18,DX18,FG18,GP18)) | GU18: =IF(A18="","",SUM(X18,BG18,CP18,DY18,FH18,GQ18)) | GV18: =IF(A18="","",SUM(Y18,ZX18,BH18,CQ18,DZ18,FI18,GR18)) | GW18: =IF(A18="","",SUM(GS18,GT18,GU18,GV18))
A19: =IF('กรอกข้อมูล นร1'!A17,'กรอกข้อมูล นร1'!A17,"") | B19: ='กรอกข้อมูล นร1'!B17&"" | C19: ='กรอกข้อมูล นร1'!D17&"" | D19: =IF('กรอกข้อมูล นร1'!C17="","",'กรอกข้อมูล นร1'!C17) | E19: =IF(A19="","",$E$6) | R19: =IF(COUNTIF($F19:$BD19," /"),COUNTIF($F19:$BD19," /"),"") | S19: =IF(COUNTIF($F19:$BD19,"ป"),COUNTIF($G19:$BD19,"ป"),"") | T19: =IF(COUNTIF($F19:$BD19,"ล"),COUNTIF($G19:$BD19,"ล"),"") | U19: =IF(COUNTIF($F19:$BD19,"ข"),COUNTIF($G19:$BD19,"ข"),"") | V19: =IF(COUNTIF($F19:$U19," /"),COUNTIF($F19:$U19," /"),"") | W19: =IF(COUNTIF($F19:$U19,"ป"),COUNTIF($F19:$U19,"ป"),"") | X19: =IF(COUNTIF($F19:$U19,"ล"),COUNTIF($F19:$U19,"ล"),"") | Y19: =IF(COUNTIF($F19:$U19,"ข"),COUNTIF($F19:$U19,"ข"),"") | BE19: =IF(COUNTIF($Z19:$BD19," /"),COUNTIF($Z19:$BD19," /"),"") | BF19: =IF(COUNTIF($Z19:$BD19,"ป"),COUNTIF($Z19:$BD19,"ป"),"") | BG19: =IF(COUNTIF($Z19:$BD19,"ล"),COUNTIF($Z19:$BD19,"ล"),"") | BH19: =IF(COUNTIF($Z19:$BD19,"ข"),COUNTIF($Z19:$BD19,"ข"),"") | CN19: =IF(COUNTIF($BI19:$CM19," /"),COUNTIF($BI19:$CM19," /"),"") | CO19: =IF(COUNTIF($BI19:$CM19,"ป"),COUNTIF($BI19:$CM19,"ป"),"") | CP19: =IF(COUNTIF($BI19:$CM19,"ล"),COUNTIF($BI19:$CM19,"ล"),"") | CQ19: =IF(COUNTIF($BI19:$CM19,"ข"),COUNTIF($BI19:$CM19,"ข"),"") | DW19: =IF(COUNTIF($CR19:$DV19," /"),COUNTIF($CR19:$DV19," /"),"") | DX19: =IF(COUNTIF($CR19:$DV19,"ป"),COUNTIF($CR19:$DV19,"ป"),"") | DY19: =IF(COUNTIF($CR19:$DV19,"ล"),COUNTIF($CR19:$DV19,"ล"),"") | DZ19: =IF(COUNTIF($CR19:$DV19,"ข"),COUNTIF($CR19:$DV19,"ข"),"") | FF19: =IF(COUNTIF($EA19:$FE19," /"),COUNTIF($EA19:$FE19," /"),"") | FG19: =IF(COUNTIF($EA19:$FE19,"ป"),COUNTIF($EA19:$FE19,"ป"),"") | FH19: =IF(COUNTIF($EA19:$FE19,"ล"),COUNTIF($EA19:$FE19,"ล"),"") | FI19: =IF(COUNTIF($EA19:$FE19,"ข"),COUNTIF($EA19:$FE19,"ข"),"") | GO19: =IF(COUNTIF($FJ19:$GN19," /"),COUNTIF($FJ19:$GN19," /"),"") | GP19: =IF(COUNTIF($FJ19:$GN19,"ป"),COUNTIF($FJ19:$GN19,"ป"),"") | GQ19: =IF(COUNTIF($FJ19:$GN19,"ล"),COUNTIF($FJ19:$GN19,"ล"),"") | GR19: =IF(COUNTIF($FJ19:$GN19,"ข"),COUNTIF($FJ19:$GN19,"ข"),"") | GS19: =IF(A19="","",SUM(V19,BE19,CN19,DW19,FF19,GO19)) | GT19: =IF(A19="","",SUM(W19,BF19,CO19,DX19,FG19,GP19)) | GU19: =IF(A19="","",SUM(X19,BG19,CP19,DY19,FH19,GQ19)) | GV19: =IF(A19="","",SUM(Y19,ZX19,BH19,CQ19,DZ19,FI19,GR19)) | GW19: =IF(A19="","",SUM(GS19,GT19,GU19,GV19))
